Workbook

Sheet 00 Legenda
A1: Indici clinici - aggregazione multi-articolo, calcolo e valutazione della pericolosita
A2: Fonti integrate: Art.1 cardiologici, Art.2 antropometrici, Art.3 profilo marziale, Art.4 indici infiammatori. Stesso soggetto dimostrativo.
A5: SCOPO | B5: Raccogliere in un unico modello formule e indici estratti dagli articoli forniti, ricalcolarli in modo trasparente dai dati grezzi del soggetto, verificare la riproducibilita dei valori pubblicati e produrre una valutazione strutturata del livello di pericolosita.
A7: AVVERTENZA | B7: Strumento didattico e di sintesi documentale. NON e un dispositivo medico e non produce diagnosi. 'Gennarino Parsifallo' e dichiarato dalla fonte stessa come caso dimostrativo, non un paziente reale. Ogni decisione clinica compete al medico.
A9: COME SI USA | B9: 1) Apri '01 Input' e modifica SOLO le celle blu su sfondo giallo. 2) Tutti gli altri fogli si ricalcolano da soli. 3) '02 Indici' contiene i 59 indici delle quattro fonti, ricalcolati e confrontati con il referto. 4) '06 Rischio' produce il punteggio complessivo di pericolosita. 5) '08 Controlli' elenca cosa e riproducibile e cosa no: leggilo prima di fidarti dei numeri.
A11: CONVENZIONI COLORE
A12: Testo blu su giallo | B12: Dato inserito a mano. E l'unica cosa da modificare.
A13: Testo nero | B13: Risultato calcolato nel foglio stesso.
A14: Testo verde | B14: Valore richiamato da un altro foglio.
A15: Riga arancione | B15: Indice fuori intervallo nella direzione critica.
A16: Riga gialla | B16: Indice dentro l'intervallo ma in zona di guardia.
A18: FOGLI
A19: 01 Input | B19: Dati grezzi del soggetto, laboratorio e fattori anamnestici. Unico foglio da compilare.
A20: 02 Indici | B20: I 59 indici delle quattro fonti: formula, valore ricalcolato, scostamento dal referto, intervallo di riferimento, stato, peso clinico e punteggio.
A21: 03 Formule | B21: Dizionario delle formule con derivazione e verifica numerica.
A22: 04 Zone FC | B22: Zone di frequenza cardiaca ricavate dalla frequenza massima.
A23: 05 Evidenze | B23: Letteratura citata dalle due fonti con PMID e applicabilita al caso.
A24: 06 Rischio | B24: Motore di calcolo: punteggio strumentale per fonte, fattori anamnestici, rischio relativo epidemiologico e indice composito di pericolosita.
A25: 07 Scenari | B25: Simulazioni what-if sugli interventi discussi dalle fonti.
A26: 08 Controlli | B26: Verifica di riproducibilita: quali valori pubblicati si riottengono dai dati grezzi e quali no.
A27: 09 Conversioni | B27: Il profilo marziale tradotto dalle unita SI a quelle di un referto di laboratorio ordinario.
A29: NOTA IMPORTANTE | B29: Il foglio '08 Controlli' registra gli scostamenti fra i valori pubblicati e il ricalcolo. I due piu rilevanti: un BMI che non discende dal peso e dall'altezza dichiarati e che si propaga su tre indici derivati, e una diagnosi di sarcopenia che poggia su una correzione di cinque millimetri la cui formula non e pubblicata. Il modello mantiene sia il valore pubblicato sia quello ricalcolato, senza sceglierne uno.
A31: AGGIUNGERE UN ARTICOLO | B31: Aggiungi le righe in fondo alle tabelle di '02 Indici', '03 Formule' e '05 Evidenze' compilando la colonna 'Fonte' con l'etichetta del nuovo articolo. Se introduce dati grezzi nuovi, inseriscili prima in '01 Input'. I conteggi di '06 Rischio' usano COUNTIFS sull'etichetta della fonte, quindi si aggiornano da soli.

Sheet 01 Input
A1: 01 - Dati grezzi del soggetto
A2: Modifica solo le celle blu su sfondo giallo. Tutto il resto del workbook si ricalcola.
A4: Parametro | B4: Valore | C4: Unita | D4: Fonte / Nota
A5: ANAGRAFICA
A6: Identificativo soggetto | B6: Gennarino Parsifallo | D6: Caso dimostrativo dichiarato dalle fonti
A7: Eta | B7: 50 | C7: anni | D7: Art.1 - Indici cardiologici / Art.2 - Indici antropometrici
A8: Sesso | B8: M | C8: M/F | D8: Determina il modello di FC massima, la stima del grasso corporeo e la formula del VAI
A10: MISURE ANTROPOMETRICHE
A11: Peso | B11: 74 | C11: kg | D11: Art.2 - Indici antropometrici
A12: Altezza | B12: 174 | C12: cm | D12: Art.2 - Indici antropometrici
A13: Circonferenza vita | B13: 97 | C13: cm | D13: Art.2 - Indici antropometrici - a fine espirazione, a meta fra ultima costa e cresta iliaca. Alimenta nove dei dodici indici antropometrici
A14: Circonferenza fianchi | B14: 100 | C14: cm | D14: Art.2 - Indici antropometrici
A15: Circonferenza polpaccio | B15: 34 | C15: cm | D15: Art.2 - Indici antropometrici - surrogato validato della massa muscolare appendicolare (PMID 30312372)
A16: Circonferenza polso | B16: 18 | C16: cm | D16: Art.2 - Indici antropometrici - misura stabile per tutta la vita adulta: e il riferimento fisso del morfotipo
A17: Peso all'eta di 30 anni | B17: 68 | C17: kg | D17: Art.2 - Indici antropometrici - serve a calcolare l'incremento ponderale ventennale
A18: Superficie corporea (BSA) | B18: 1.9 | C18: m2 | D18: Art.1 - Indici cardiologici - riportata come 'circa 1,9 m2'; denominatore degli indici cardiologici indicizzati
A20: MISURE CARDIOVASCOLARI
A21: Pressione sistolica (SBP) | B21: 128 | C21: mmHg | D21: Art.1 - Indici cardiologici
A22: Pressione diastolica (DBP) | B22: 84 | C22: mmHg | D22: Art.1 - Indici cardiologici
A23: Frequenza cardiaca a riposo (FC) | B23: 82 | C23: bpm | D23: Art.1 - Indici cardiologici - unico indice cardiologico fuori range del referto
A24: Gittata sistolica (SV) | B24: 66 | C24: mL | D24: Art.1 - Indici cardiologici
A25: Frequenza cardiaca massima da referto | B25: 175 | C25: bpm | D25: Art.1 - Indici cardiologici - modello logistico sesso-specifico (PMID 12752560 / 11722475); i coefficienti non sono pubblicati, quindi il valore si inserisce a mano
A26: Pressione venosa centrale assunta (CVP) | B26: 5 | C26: mmHg | D26: ASSUNZIONE: non riportata dalle fonti. Serve solo alle resistenze vascolari. Con CVP=5 il calcolo restituisce i 2,7 kU*m2 del referto
A28: LABORATORIO
A29: Colesterolo HDL | B29: 41 | C29: mg/dL | D29: Art.2 - Indici antropometrici - preso da solo nessun laboratorio lo segnalerebbe. Alimenta CMI e VAI
A30: Trigliceridi | B30: 148 | C30: mg/dL | D30: Art.2 - Indici antropometrici - idem. Alimenta LAP, CMI e VAI
A32: PROFILO MARZIALE (valori misurati)
A33: Sideremia | B33: 13.6 | C33: uM | D33: Art.3 - Profilo marziale - ritmo circadiano marcato: il prelievo va fatto al mattino a digiuno, altrimenti la saturazione risulta abbassata di diversi punti senza che le riserve siano cambiate
A34: Transferrina | B34: 39.2 | C34: uM | D34: Art.3 - Profilo marziale - il fegato ne produce di piu proprio quando il ferro scarseggia. Da qui derivano TIBC e UIBC
A35: Ferritina | B35: 160.9 | C35: pM | D35: Art.3 - Profilo marziale - proteina di fase acuta positiva: sale con l'infiammazione a prescindere da quanto ferro contenga
A36: Fattore di aggiustamento BRINDA - sideremia | B36: 1.2574 | C36: - | D36: DEDOTTO: rapporto fra il valore aggiustato e quello grezzo pubblicati (17,1/13,6). I marcatori di infiammazione su cui si basa la correzione non sono riportati dall'articolo
A37: Fattore di aggiustamento BRINDA - ferritina | B37: 0.7502 | C37: - | D37: DEDOTTO: rapporto fra il valore aggiustato e quello grezzo pubblicati (120,7/160,9). Corrisponde a una riduzione del 25% esatto
A39: INFIAMMAZIONE - misure dirette
A40: Proteina C reattiva (PCR) | B40: 0.3 | C40: mg/dL | D40: Art.4 - Indici infiammatori - proteina di fase acuta: sale molto e in fretta nell'infiammazione acuta, ed e per questo un cattivo strumento per quella cronica di basso grado
A41: VES a 1 ora | B41: 14 | C41: mm | D41: Art.4 - Indici infiammatori - misura una proprieta reologica del sangue che cambia nell'arco di giorni
A42: Omocisteina | B42: 14.6 | C42: uM | D42: Art.4 - Indici infiammatori
A43: Uricemia | B43: 6.7 | C43: mg/dL | D43: Art.4 - Indici infiammatori
A45: EMOCROMO - valori ricostruiti per inversione degli indici
A46: Piastrine | B46: 272 | C46: 10^9/L | D46: DEDOTTO da AISI/SIRI. L'articolo non pubblica l'emocromo assoluto: i valori di questa sezione sono stati ricavati invertendo gli indici derivati
A47: Linfociti | B47: 1.7407 | C47: 10^9/L | D47: DEDOTTO da (AISI/SII)/MLR
...

Sheet 02 Indici
A1: 02 - Indici estratti dalle fonti, ricalcolati e valutati
A2: Colonna E ricalcolata dai dati grezzi del foglio 01. Colonna G riporta il valore pubblicato: la colonna H rende visibile ogni scostamento.
A4: # | B4: Gruppo | C4: Indice | D4: Formula | E4: Valore calcolato | F4: Unita | G4: Valore referto | H4: Scost. % | I4: Rif. min | J4: Rif. max | K4: Direzione critica | L4: Posiz. range | M4: Stato | N4: Peso | O4: Punt. 0-3 | P4: Contrib. | Q4: Fonte | R4: Note e interpretazione
A5: 1 | B5: Pressori | C5: Pressione sistolica | D5: misurata | E5: ='01 Input'!$B$21 -> 128 | F5: mmHg | G5: 128 | H5: =IF(G5=0,"",(E5-G5)/ABS(G5)) -> 0 | I5: 100 | J5: 129 | K5: Alto | L5: =IF(J5=I5,"",(E5-I5)/(J5-I5)) -> 0.96551724 | M5: =IF(E5>J5,"Fuori (alto)",IF(E5<I5,"Fuori (basso)",IF(AND(K5<>"Informativo",OR(AND(OR(K5="Alto",K5="Bilaterale"),L5>0.8),AND(OR(K5="Basso",K5="Bilaterale"),L5<0.2))),"Borderline","Normale"))) -> Borderline | N5: 1 | O5: =IF(N5=0,0,IF(AND(E5>J5,OR(K5="Alto",K5="Bilaterale")),IF((E5-J5)/(J5-I5)>0.1,3,2),IF(AND(E5<I5,OR(K5="Basso",K5="Bilaterale")),IF((I5-E5)/(J5-I5)>0.1,3,2),IF(M5="Borderline",1,0)))) -> 1 | P5: =N5*O5 -> 1 | Q5: Art.1 - Indici cardiologici | R5: Dentro l'intervallo ma a 1 mmHg dal limite superiore.
A6: 2 | B6: Pressori | C6: Pressione diastolica | D6: misurata | E6: ='01 Input'!$B$22 -> 84 | F6: mmHg | G6: 84 | H6: =IF(G6=0,"",(E6-G6)/ABS(G6)) -> 0 | I6: 60 | J6: 84 | K6: Alto | L6: =IF(J6=I6,"",(E6-I6)/(J6-I6)) -> 1 | M6: =IF(E6>J6,"Fuori (alto)",IF(E6<I6,"Fuori (basso)",IF(AND(K6<>"Informativo",OR(AND(OR(K6="Alto",K6="Bilaterale"),L6>0.8),AND(OR(K6="Basso",K6="Bilaterale"),L6<0.2))),"Borderline","Normale"))) -> Borderline | N6: 1 | O6: =IF(N6=0,0,IF(AND(E6>J6,OR(K6="Alto",K6="Bilaterale")),IF((E6-J6)/(J6-I6)>0.1,3,2),IF(AND(E6<I6,OR(K6="Basso",K6="Bilaterale")),IF((I6-E6)/(J6-I6)>0.1,3,2),IF(M6="Borderline",1,0)))) -> 1 | P6: =N6*O6 -> 1 | Q6: Art.1 - Indici cardiologici | R6: Esattamente sul limite superiore. La fonte segnala che la soglia contera quando entrera in uno score.
A7: 3 | B7: Pressori | C7: Pressione arteriosa media (MAP) | D7: DBP + 0,4 x PP | E7: =E6+0.4*E8 -> 101.6 | F7: mmHg | G7: 101 | H7: =IF(G7=0,"",(E7-G7)/ABS(G7)) -> 0.0059405941 | I7: 70 | J7: 105 | K7: Alto | L7: =IF(J7=I7,"",(E7-I7)/(J7-I7)) -> 0.90285714 | M7: =IF(E7>J7,"Fuori (alto)",IF(E7<I7,"Fuori (basso)",IF(AND(K7<>"Informativo",OR(AND(OR(K7="Alto",K7="Bilaterale"),L7>0.8),AND(OR(K7="Basso",K7="Bilaterale"),L7<0.2))),"Borderline","Normale"))) -> Borderline | N7: 1 | O7: =IF(N7=0,0,IF(AND(E7>J7,OR(K7="Alto",K7="Bilaterale")),IF((E7-J7)/(J7-I7)>0.1,3,2),IF(AND(E7<I7,OR(K7="Basso",K7="Bilaterale")),IF((I7-E7)/(J7-I7)>0.1,3,2),IF(M7="Borderline",1,0)))) -> 1 | P7: =N7*O7 -> 1 | Q7: Art.1 - Indici cardiologici | R7: La MAP classica (SBP+2xDBP)/3 darebbe 98,7 e non 101: il valore pubblicato si riproduce solo con DBP + 0,4 x PP. La scelta si propaga sul Modified Shock Index, che ha la MAP al denominatore.
A8: 4 | B8: Pressori | C8: Pressione di pulsazione (PP) | D8: SBP - DBP | E8: =E5-E6 -> 44 | F8: mmHg | G8: 44 | H8: =IF(G8=0,"",(E8-G8)/ABS(G8)) -> 0 | I8: 30 | J8: 55 | K8: Alto | L8: =IF(J8=I8,"",(E8-I8)/(J8-I8)) -> 0.56 | M8: =IF(E8>J8,"Fuori (alto)",IF(E8<I8,"Fuori (basso)",IF(AND(K8<>"Informativo",OR(AND(OR(K8="Alto",K8="Bilaterale"),L8>0.8),AND(OR(K8="Basso",K8="Bilaterale"),L8<0.2))),"Borderline","Normale"))) -> Normale | N8: 2 | O8: =IF(N8=0,0,IF(AND(E8>J8,OR(K8="Alto",K8="Bilaterale")),IF((E8-J8)/(J8-I8)>0.1,3,2),IF(AND(E8<I8,OR(K8="Basso",K8="Bilaterale")),IF((I8-E8)/(J8-I8)>0.1,3,2),IF(M8="Borderline",1,0)))) -> 0 | P8: =N8*O8 -> 0 | Q8: Art.1 - Indici cardiologici | R8: Marcatore di elasticita dei grossi vasi e di invecchiamento vascolare (PMID 33793325). Dentro il range: da sorvegliare, non da segnalare.
A9: 5 | B9: Dinamici | C9: Frequenza cardiaca a riposo | D9: misurata | E9: ='01 Input'!$B$23 -> 82 | F9: bpm | G9: 82 | H9: =IF(G9=0,"",(E9-G9)/ABS(G9)) -> 0 | I9: 72 | J9: 76 | K9: Alto | L9: =IF(J9=I9,"",(E9-I9)/(J9-I9)) -> 2.5 | M9: =IF(E9>J9,"Fuori (alto)",IF(E9<I9,"Fuori (basso)",IF(AND(K9<>"Informativo",OR(AND(OR(K9="Alto",K9="Bilaterale"),L9>0.8),AND(OR(K9="Basso",K9="Bilaterale"),L9<0.2))),"Borderline","Normale"))) -> Fuori (alto) | N9: 3 | O9: =IF(N9=0,0,IF(AND(E9>J9,OR(K9="Alto",K9="Bilaterale")),IF((E9-J9)/(J9-I9)>0.1,3,2),IF(AND(E9<I9,OR(K9="Basso",K9="Bilaterale")),IF((I9-E9)/(J9-I9)>0.1,3,2),IF(M9="Borderline",1,0)))) -> 3 | P9: =N9*O9 -> 9 | Q9: Art.1 - Indici cardiologici | R9: Unico indice cardiologico fuori range, liquidato come 'tachicardia lieve'. E anche quello con il supporto epidemiologico piu solido, ed e il motore aritmetico di meta degli altri indici della sezione.
A10: 6 | B10: Dinamici | C10: Frequenza cardiaca massima stimata | D10: modello logistico sesso-specifico | E10: ='01 Input'!$B$25 -> 175 | F10: bpm | G10: 175 | H10: =IF(G10=0,"",(E10-G10)/ABS(G10)) -> 0 | I10: 158 | J10: 192 | K10: Informativo | L10: =IF(J10=I10,"",(E10-I10)/(J10-I10)) -> 0.5 | M10: =IF(E10>J10,"Fuori (alto)",IF(E10<I10,"Fuori (basso)",IF(AND(K10<>"Informativo",OR(AND(OR(K10="Alto",K10="Bilaterale"),L10>0.8),AND(OR(K10="Basso",K10="Bilaterale"),L10<0.2))),"Borderline","Normale"))) -> Normale | N10: 0 | O10: =IF(N10=0,0,IF(AND(E10>J10,OR(K10="Alto",K10="Bilaterale")),IF((E10-J10)/(J10-I10)>0.1,3,2),IF(AND(E10<I10,OR(K10="Basso",K10="Bilaterale")),IF((I10-E10)/(J10-I10)>0.1,3,2),IF(M10="Borderline",1,0)))) -> 0 | P10: =N10*O10 -> 0 | Q10: Art.1 - Indici cardiologici | R10: Stima anagrafica, non misura: non descrive lo stato del soggetto, quindi peso 0. L'intervallo 158-192 e il 90-110% del predetto. Confronto con 220-eta (170) e Tanaka (173) nel foglio 03.
A11: 7 | B11: Dinamici | C11: Frequenza cardiaca di riserva | D11: FC max - FC riposo | E11: =E10-E9 -> 93 | F11: bpm | G11: 93 | H11: =IF(G11=0,"",(E11-G11)/ABS(G11)) -> 0 | I11: 70 | J11: 120 | K11: Basso | L11: =IF(J11=I11,"",(E11-I11)/(J11-I11)) -> 0.46 | M11: =IF(E11>J11,"Fuori (alto)",IF(E11<I11,"Fuori (basso)",IF(AND(K11<>"Informativo",OR(AND(OR(K11="Alto",K11="Bilaterale"),L11>0.8),AND(OR(K11="Basso",K11="Bilaterale"),L11<0.2))),"Borderline","Normale"))) -> Normale | N11: 1 | O11: =IF(N11=0,0,IF(AND(E11>J11,OR(K11="Alto",K11="Bilaterale")),IF((E11-J11)/(J11-I11)>0.1,3,2),IF(AND(E11<I11,OR(K11="Basso",K11="Bilaterale")),IF((I11-E11)/(J11-I11)>0.1,3,2),IF(M11="Borderline",1,0)))) -> 0 | P11: =N11*O11 -> 0 | Q11: Art.1 - Indici cardiologici | R11: Formalmente normale, ma alta perche la FC massima e alta per eta, non perche il basale sia buono. Con basale 72 salirebbe a 103 senza alcun miglioramento reale. HR 2,8 per mortalita CV in chi non impegna l'80% della riserva (PMID 17446799).
A12: 8 | B12: Dinamici | C12: Modified Shock Index (MSI) | D12: FC riposo / MAP | E12: =E9/E7 -> 0.80708661 | F12: - | G12: 0.81 | H12: =IF(G12=0,"",(E12-G12)/ABS(G12)) -> -0.0035967726 | I12: 0.7 | J12: 0.99 | K12: Alto | L12: =IF(J12=I12,"",(E12-I12)/(J12-I12)) -> 0.36926419 | M12: =IF(E12>J12,"Fuori (alto)",IF(E12<I12,"Fuori (basso)",IF(AND(K12<>"Informativo",OR(AND(OR(K12="Alto",K12="Bilaterale"),L12>0.8),AND(OR(K12="Basso",K12="Bilaterale"),L12<0.2))),"Borderline","Normale"))) -> Normale | N12: 1 | O12: =IF(N12=0,0,IF(AND(E12>J12,OR(K12="Alto",K12="Bilaterale")),IF((E12-J12)/(J12-I12)>0.1,3,2),IF(AND(E12<I12,OR(K12="Basso",K12="Bilaterale")),IF((I12-E12)/(J12-I12)>0.1,3,2),IF(M12="Borderline",1,0)))) -> 0 | P12: =N12*O12 -> 0 | Q12: Art.1 - Indici cardiologici | R12: Va calcolato sulla pressione MEDIA, non sulla sistolica: con la sistolica verrebbe 0,64, errore diffuso nei calcolatori online.
A13: 9 | B13: Dinamici | C13: Prodotto cardiovascolare (RPP) | D13: FC riposo x SBP | E13: =E9*E5 -> 10496 | F13: bpm*mmHg | G13: 10496 | H13: =IF(G13=0,"",(E13-G13)/ABS(G13)) -> 0 | I13: 10000 | J13: 14999 | K13: Alto | L13: =IF(J13=I13,"",(E13-I13)/(J13-I13)) -> 0.099219844 | M13: =IF(E13>J13,"Fuori (alto)",IF(E13<I13,"Fuori (basso)",IF(AND(K13<>"Informativo",OR(AND(OR(K13="Alto",K13="Bilaterale"),L13>0.8),AND(OR(K13="Basso",K13="Bilaterale"),L13<0.2))),"Borderline","Normale"))) -> Normale | N13: 2 | O13: =IF(N13=0,0,IF(AND(E13>J13,OR(K13="Alto",K13="Bilaterale")),IF((E13-J13)/(J13-I13)>0.1,3,2),IF(AND(E13<I13,OR(K13="Basso",K13="Bilaterale")),IF((I13-E13)/(J13-I13)>0.1,3,2),IF(M13="Borderline",1,0)))) -> 0 | P13: =N13*O13 -> 0 | Q13: Art.1 - Indici cardiologici | R13: Surrogato non invasivo del consumo miocardico di ossigeno (PMID 38453019). Il soggetto e entrato nella fascia per 496 punti, spinto dalla frequenza. Tre mesi di esercizio supervisionato lo abbassano del 19% (PMID 15793048).
A14: 10 | B14: Pompa | C14: Gittata sistolica (SV) | D14: misurata | E14: ='01 Input'!$B$24 -> 66 | F14: mL | G14: 66 | H14: =IF(G14=0,"",(E14-G14)/ABS(G14)) -> 0 | I14: 60 | J14: 100 | K14: Basso | L14: =IF(J14=I14,"",(E14-I14)/(J14-I14)) -> 0.15 | M14: =IF(E14>J14,"Fuori (alto)",IF(E14<I14,"Fuori (basso)",IF(AND(K14<>"Informativo",OR(AND(OR(K14="Alto",K14="Bilaterale"),L14>0.8),AND(OR(K14="Basso",K14="Bilaterale"),L14<0.2))),"Borderline","Normale"))) -> Borderline | N14: 2 | O14: =IF(N14=0,0,IF(AND(E14>J14,OR(K14="Alto",K14="Bilaterale")),IF((E14-J14)/(J14-I14)>0.1,3,2),IF(AND(E14<I14,OR(K14="Basso",K14="Bilaterale")),IF((I14-E14)/(J14-I14)>0.1,3,2),IF(M14="Borderline",1,0)))) -> 1 | P14: =N14*O14 -> 2 | Q14: Art.1 - Indici cardiologici | R14: Nel 15% piu basso dell'intervallo: e la pompa poco capiente che obbliga il cuore a compensare con la frequenza. E l'indice che spiega perche gli 82 battiti esistono.
A15: 11 | B15: Pompa | C15: Portata cardiaca (CO) | D15: SV x FC / 1000 | E15: =E14*E9/1000 -> 5.412 | F15: L/min | G15: 5.4 | H15: =IF(G15=0,"",(E15-G15)/ABS(G15)) -> 0.0022222222 | I15: 3.5 | J15: 6.9 | K15: Basso | L15: =IF(J15=I15,"",(E15-I15)/(J15-I15)) -> 0.56235294 | M15: =IF(E15>J15,"Fuori (alto)",IF(E15<I15,"Fuori (basso)",IF(AND(K15<>"Informativo",OR(AND(OR(K15="Alto",K15="Bilaterale"),L15>0.8),AND(OR(K15="Basso",K15="Bilaterale"),L15<0.2))),"Borderline","Normale"))) -> Normale | N15: 1 | O15: =IF(N15=0,0,IF(AND(E15>J15,OR(K15="Alto",K15="Bilaterale")),IF((E15-J15)/(J15-I15)>0.1,3,2),IF(AND(E15<I15,OR(K15="Basso",K15="Bilaterale")),IF((I15-E15)/(J15-I15)>0.1,3,2),IF(M15="Borderline",1,0)))) -> 0 | P15: =N15*O15 -> 0 | Q15: Art.1 - Indici cardiologici | R15: Il risultato finale e adeguato, ed e per questo che il referto scrive 'normale'. Lo stesso valore si ottiene con SV 80 mL e 68 bpm: identico output, meccanismo diverso.
A16: 12 | B16: Pompa | C16: Cardiac Index (CI) | D16: CO / BSA | E16: =E15/'01 Input'!$B$18 -> 2.8484211 | F16: L/min/m2 | G16: 2.8 | H16: =IF(G16=0,"",(E16-G16)/ABS(G16)) -> 0.017293233 | I16: 2.5 | J16: 3.9 | K16: Basso | L16: =IF(J16=I16,"",(E16-I16)/(J16-I16)) -> 0.24887218 | M16: =IF(E16>J16,"Fuori (alto)",IF(E16<I16,"Fuori (basso)",IF(AND(K16<>"Informativo",OR(AND(OR(K16="Alto",K16="Bilaterale"),L16>0.8),AND(OR(K16="Basso",K16="Bilaterale"),L16<0.2))),"Borderline","Normale"))) -> Normale | N16: 1 | O16: =IF(N16=0,0,IF(AND(E16>J16,OR(K16="Alto",K16="Bilaterale")),IF((E16-J16)/(J16-I16)>0.1,3,2),IF(AND(E16<I16,OR(K16="Basso",K16="Bilaterale")),IF((I16-E16)/(J16-I16)>0.1,3,2),IF(M16="Borderline",1,0)))) -> 0 | P16: =N16*O16 -> 0 | Q16: Art.1 - Indici cardiologici | R16: Portata indicizzata per superficie corporea. Nel terzo inferiore dell'intervallo.
A17: 13 | B17: Pompa | C17: Left Cardiac Work Index (LCWI) | D17: CI x MAP x 2,222 | E17: =E16*E7*2.222 -> 643.04586 | F17: mW/m2 | G17: 627 | H17: =IF(G17=0,"",(E17-G17)/ABS(G17)) -> 0.02559149 | I17: 400 | J17: 900 | K17: Bilaterale | L17: =IF(J17=I17,"",(E17-I17)/(J17-I17)) -> 0.48609173 | M17: =IF(E17>J17,"Fuori (alto)",IF(E17<I17,"Fuori (basso)",IF(AND(K17<>"Informativo",OR(AND(OR(K17="Alto",K17="Bilaterale"),L17>0.8),AND(OR(K17="Basso",K17="Bilaterale"),L17<0.2))),"Borderline","Normale"))) -> Normale | N17: 1 | O17: =IF(N17=0,0,IF(AND(E17>J17,OR(K17="Alto",K17="Bilaterale")),IF((E17-J17)/(J17-I17)>0.1,3,2),IF(AND(E17<I17,OR(K17="Basso",K17="Bilaterale")),IF((I17-E17)/(J17-I17)>0.1,3,2),IF(M17="Borderline",1,0)))) -> 0 | P17: =N17*O17 -> 0 | Q17: Art.1 - Indici cardiologici | R17: La costante 2,222 converte L/min x mmHg in milliwatt (1 L/min = 1,667e-5 m3/s; 1 mmHg = 133,322 Pa). Ricalcolando con il CI e la MAP non arrotondati si ottengono 643 contro i 627 pubblicati: differenza di solo arrotondamento.
A18: 14 | B18: Pompa | C18: Indice di rigidita arteriosa | D18: PP / MAP | E18: =E8/E7 -> 0.43307087 | F18: - | G18: 0.44 | H18: =IF(G18=0,"",(E18-G18)/ABS(G18)) -> -0.015748031 | I18: 0.3 | J18: 0.55 | K18: Alto | L18: =IF(J18=I18,"",(E18-I18)/(J18-I18)) -> 0.53228346 | M18: =IF(E18>J18,"Fuori (alto)",IF(E18<I18,"Fuori (basso)",IF(AND(K18<>"Informativo",OR(AND(OR(K18="Alto",K18="Bilaterale"),L18>0.8),AND(OR(K18="Basso",K18="Bilaterale"),L18<0.2))),"Borderline","Normale"))) -> Normale | N18: 2 | O18: =IF(N18=0,0,IF(AND(E18>J18,OR(K18="Alto",K18="Bilaterale")),IF((E18-J18)/(J18-I18)>0.1,3,2),IF(AND(E18<I18,OR(K18="Basso",K18="Bilaterale")),IF((I18-E18)/(J18-I18)>0.1,3,2),IF(M18="Borderline",1,0)))) -> 0 | P18: =N18*O18 -> 0 | Q18: Art.1 - Indici cardiologici | R18: Rapporto fra componente pulsatile e continua. Ricostruito per riproduzione numerica: PP/MAP da 0,436, mentre PP/SBP darebbe 0,34.
A19: 15 | B19: Pompa | C19: Resistenze vascolari sistemiche (SVRI) | D19: 80 x (MAP - CVP) / CI / 1000 | E19: =80*(E7-'01 Input'!$B$26)/E16/1000 -> 2.713082 | F19: kU*m2 | G19: 2.7 | H19: =IF(G19=0,"",(E19-G19)/ABS(G19)) -> 0.0048452 | I19: 1.8 | J19: 2.8 | K19: Alto | L19: =IF(J19=I19,"",(E19-I19)/(J19-I19)) -> 0.91308204 | M19: =IF(E19>J19,"Fuori (alto)",IF(E19<I19,"Fuori (basso)",IF(AND(K19<>"Informativo",OR(AND(OR(K19="Alto",K19="Bilaterale"),L19>0.8),AND(OR(K19="Basso",K19="Bilaterale"),L19<0.2))),"Borderline","Normale"))) -> Borderline | N19: 2 | O19: =IF(N19=0,0,IF(AND(E19>J19,OR(K19="Alto",K19="Bilaterale")),IF((E19-J19)/(J19-I19)>0.1,3,2),IF(AND(E19<I19,OR(K19="Basso",K19="Bilaterale")),IF((I19-E19)/(J19-I19)>0.1,3,2),IF(M19="Borderline",1,0)))) -> 1 | P19: =N19*O19 -> 2 | Q19: Art.1 - Indici cardiologici | R19: A 0,1 dal limite superiore: le arterie oppongono resistenza vicina al massimo tollerato e il cuore risponde con la frequenza, non aumentando il volume di eiezione. CVP non pubblicata, assunta a 5 mmHg.
A20: 16 | B20: Antropom. | C20: Superficie corporea (BSA) | D20: input (formula non pubblicata) | E20: ='01 Input'!$B$18 -> 1.9 | F20: m2 | G20: 1.9 | H20: =IF(G20=0,"",(E20-G20)/ABS(G20)) -> 0 | I20: 1.5 | J20: 2.3 | K20: Informativo | L20: =IF(J20=I20,"",(E20-I20)/(J20-I20)) -> 0.5 | M20: =IF(E20>J20,"Fuori (alto)",IF(E20<I20,"Fuori (basso)",IF(AND(K20<>"Informativo",OR(AND(OR(K20="Alto",K20="Bilaterale"),L20>0.8),AND(OR(K20="Basso",K20="Bilaterale"),L20<0.2))),"Borderline","Normale"))) -> Normale | N20: 0 | O20: =IF(N20=0,0,IF(AND(E20>J20,OR(K20="Alto",K20="Bilaterale")),IF((E20-J20)/(J20-I20)>0.1,3,2),IF(AND(E20<I20,OR(K20="Basso",K20="Bilaterale")),IF((I20-E20)/(J20-I20)>0.1,3,2),IF(M20="Borderline",1,0)))) -> 0 | P20: =N20*O20 -> 0 | Q20: Art.1 - Indici cardiologici | R20: Inclusa come sedicesima riga: la fonte dichiara 16 indici cardiologici ma ne tabula 15. E il denominatore di CI, LCWI e SVRI. Peso 0.
A21: 17 | B21: Base | C21: Indice di massa corporea (BMI) | D21: peso / altezza^2 | E21: ='01 Input'!$B$11/('01 Input'!$B$12/100)^2 -> 24.441802 | F21: kg/m2 | G21: 24.09 | H21: =IF(G21=0,"",(E21-G21)/ABS(G21)) -> 0.014603657 | I21: 18.5 | J21: 24.9 | K21: Informativo | L21: =IF(J21=I21,"",(E21-I21)/(J21-I21)) -> 0.92840658 | M21: =IF(E21>J21,"Fuori (alto)",IF(E21<I21,"Fuori (basso)",IF(AND(K21<>"Informativo",OR(AND(OR(K21="Alto",K21="Bilaterale"),L21>0.8),AND(OR(K21="Basso",K21="Bilaterale"),L21<0.2))),"Borderline","Normale"))) -> Normale | N21: 0 | O21: =IF(N21=0,0,IF(AND(E21>J21,OR(K21="Alto",K21="Bilaterale")),IF((E21-J21)/(J21-I21)>0.1,3,2),IF(AND(E21<I21,OR(K21="Basso",K21="Bilaterale")),IF((I21-E21)/(J21-I21)>0.1,3,2),IF(M21="Borderline",1,0)))) -> 0 | P21: =N21*O21 -> 0 | Q21: Art.2 - Indici antropometrici | R21: ATTENZIONE: 74 kg su 174 cm danno 24,44, non i 24,09 pubblicati. Il referto usa internamente 24,09 (il VAI torna solo con quel valore). Peso 0 non perche sia irrilevante, ma perche e proprio l'indice che qui assolve un corpo in disordine. Vedi foglio 08.
A22: 18 | B22: Base | C22: Rapporto altezza / polso | D22: altezza / circonf. polso | E22: ='01 Input'!$B$12/'01 Input'!$B$16 -> 9.6666667 | F22: - | G22: 9.7 | H22: =IF(G22=0,"",(E22-G22)/ABS(G22)) -> -0.0034364261 | I22: 9.6 | J22: 10.4 | K22: Informativo | L22: =IF(J22=I22,"",(E22-I22)/(J22-I22)) -> 0.083333333 | M22: =IF(E22>J22,"Fuori (alto)",IF(E22<I22,"Fuori (basso)",IF(AND(K22<>"Informativo",OR(AND(OR(K22="Alto",K22="Bilaterale"),L22>0.8),AND(OR(K22="Basso",K22="Bilaterale"),L22<0.2))),"Borderline","Normale"))) -> Normale | N22: 0 | O22: =IF(N22=0,0,IF(AND(E22>J22,OR(K22="Alto",K22="Bilaterale")),IF((E22-J22)/(J22-I22)>0.1,3,2),IF(AND(E22<I22,OR(K22="Basso",K22="Bilaterale")),IF((I22-E22)/(J22-I22)>0.1,3,2),IF(M22="Borderline",1,0)))) -> 0 | P22: =N22*O22 -> 0 | Q22: Art.2 - Indici antropometrici | R22: Morfotipo normolineo. Al polso non c'e ne grasso apprezzabile ne ventre muscolare: e l'unica misura stabile per tutta la vita adulta, e quindi il riferimento fisso contro cui si giudicano gli indici che invece si muovono.
A23: 19 | B23: Base | C23: Peso ideale secondo Lorenz | D23: H - 100 - (H - 150)/4 | E23: ='01 Input'!$B$12-100-('01 Input'!$B$12-150)/4 -> 68 | F23: kg | G23: 68 | H23: =IF(G23=0,"",(E23-G23)/ABS(G23)) -> 0 | I23: 60 | J23: 80 | K23: Informativo | L23: =IF(J23=I23,"",(E23-I23)/(J23-I23)) -> 0.4 | M23: =IF(E23>J23,"Fuori (alto)",IF(E23<I23,"Fuori (basso)",IF(AND(K23<>"Informativo",OR(AND(OR(K23="Alto",K23="Bilaterale"),L23>0.8),AND(OR(K23="Basso",K23="Bilaterale"),L23<0.2))),"Borderline","Normale"))) -> Normale | N23: 0 | O23: =IF(N23=0,0,IF(AND(E23>J23,OR(K23="Alto",K23="Bilaterale")),IF((E23-J23)/(J23-I23)>0.1,3,2),IF(AND(E23<I23,OR(K23="Basso",K23="Bilaterale")),IF((I23-E23)/(J23-I23)>0.1,3,2),IF(M23="Borderline",1,0)))) -> 0 | P23: =N23*O23 -> 0 | Q23: Art.2 - Indici antropometrici | R23: Lavora sulla sola statura e ignora eta e corporatura. Estremo basso della forbice del peso desiderabile.
A24: 20 | B24: Base | C24: Peso ideale secondo Creff | D24: (H - 100 + eta/10) x 0,9 | E24: =('01 Input'!$B$12-100+'01 Input'!$B$7/10)*0.9 -> 71.1 | F24: kg | G24: 71.1 | H24: =IF(G24=0,"",(E24-G24)/ABS(G24)) -> 0 | I24: 60 | J24: 80 | K24: Informativo | L24: =IF(J24=I24,"",(E24-I24)/(J24-I24)) -> 0.555 | M24: =IF(E24>J24,"Fuori (alto)",IF(E24<I24,"Fuori (basso)",IF(AND(K24<>"Informativo",OR(AND(OR(K24="Alto",K24="Bilaterale"),L24>0.8),AND(OR(K24="Basso",K24="Bilaterale"),L24<0.2))),"Borderline","Normale"))) -> Normale | N24: 0 | O24: =IF(N24=0,0,IF(AND(E24>J24,OR(K24="Alto",K24="Bilaterale")),IF((E24-J24)/(J24-I24)>0.1,3,2),IF(AND(E24<I24,OR(K24="Basso",K24="Bilaterale")),IF((I24-E24)/(J24-I24)>0.1,3,2),IF(M24="Borderline",1,0)))) -> 0 | P24: =N24*O24 -> 0 | Q24: Art.2 - Indici antropometrici | R24: Corregge per eta e morfotipo. Con Lorenz definisce la forbice 68-71 kg: il soggetto a 74 kg sfora di meno di tre chili, margine che nessun clinico definirebbe allarmante. Il problema non e quanto pesa ma dove.
A25: 21 | B25: Forma | C25: Rapporto vita / altezza (WHtR) | D25: vita / altezza | E25: ='01 Input'!$B$13/'01 Input'!$B$12 -> 0.55747126 | F25: - | G25: 0.56 | H25: =IF(G25=0,"",(E25-G25)/ABS(G25)) -> -0.0045155993 | I25: 0.3 | J25: 0.52 | K25: Alto | L25: =IF(J25=I25,"",(E25-I25)/(J25-I25)) -> 1.1703239 | M25: =IF(E25>J25,"Fuori (alto)",IF(E25<I25,"Fuori (basso)",IF(AND(K25<>"Informativo",OR(AND(OR(K25="Alto",K25="Bilaterale"),L25>0.8),AND(OR(K25="Basso",K25="Bilaterale"),L25<0.2))),"Borderline","Normale"))) -> Fuori (alto) | N25: 3 | O25: =IF(N25=0,0,IF(AND(E25>J25,OR(K25="Alto",K25="Bilaterale")),IF((E25-J25)/(J25-I25)>0.1,3,2),IF(AND(E25<I25,OR(K25="Basso",K25="Bilaterale")),IF((I25-E25)/(J25-I25)>0.1,3,2),IF(M25="Borderline",1,0)))) -> 3 | P25: =N25*O25 -> 9 | Q25: Art.2 - Indici antropometrici | R25: La regola aurea vuole la vita sotto la meta dell'altezza. Meta-analisi di 31 studi: discrimina il rischio cardiometabolico meglio del BMI (PMID 22106927). E il primo indice da guardare, per velocita e robustezza.
A26: 22 | B26: Forma | C26: Rapporto vita / fianchi (WHR) | D26: vita / fianchi | E26: ='01 Input'!$B$13/'01 Input'!$B$14 -> 0.97 | F26: - | G26: 0.97 | H26: =IF(G26=0,"",(E26-G26)/ABS(G26)) -> 0 | I26: 0.7 | J26: 0.89 | K26: Alto | L26: =IF(J26=I26,"",(E26-I26)/(J26-I26)) -> 1.4210526 | M26: =IF(E26>J26,"Fuori (alto)",IF(E26<I26,"Fuori (basso)",IF(AND(K26<>"Informativo",OR(AND(OR(K26="Alto",K26="Bilaterale"),L26>0.8),AND(OR(K26="Basso",K26="Bilaterale"),L26<0.2))),"Borderline","Normale"))) -> Fuori (alto) | N26: 2 | O26: =IF(N26=0,0,IF(AND(E26>J26,OR(K26="Alto",K26="Bilaterale")),IF((E26-J26)/(J26-I26)>0.1,3,2),IF(AND(E26<I26,OR(K26="Basso",K26="Bilaterale")),IF((I26-E26)/(J26-I26)>0.1,3,2),IF(M26="Borderline",1,0)))) -> 3 | P26: =N26*O26 -> 6 | Q26: Art.2 - Indici antropometrici | R26: Forma a mela: distribuzione addominale del grasso, la peggiore dal punto di vista metabolico.
A27: 23 | B27: Forma | C27: Conicity Index | D27: (vita/100) / (0,109 x RADQ(peso/altezza_m)) | E27: =('01 Input'!$B$13/100)/(0.109*SQRT('01 Input'!$B$11/('01 Input'!$B$12/100))) -> 1.3645957 | F27: - | G27: 1.36 | H27: =IF(G27=0,"",(E27-G27)/ABS(G27)) -> 0.0033791962 | I27: 1 | J27: 1.25 | K27: Alto | L27: =IF(J27=I27,"",(E27-I27)/(J27-I27)) -> 1.4583828 | M27: =IF(E27>J27,"Fuori (alto)",IF(E27<I27,"Fuori (basso)",IF(AND(K27<>"Informativo",OR(AND(OR(K27="Alto",K27="Bilaterale"),L27>0.8),AND(OR(K27="Basso",K27="Bilaterale"),L27<0.2))),"Borderline","Normale"))) -> Fuori (alto) | N27: 2 | O27: =IF(N27=0,0,IF(AND(E27>J27,OR(K27="Alto",K27="Bilaterale")),IF((E27-J27)/(J27-I27)>0.1,3,2),IF(AND(E27<I27,OR(K27="Basso",K27="Bilaterale")),IF((I27-E27)/(J27-I27)>0.1,3,2),IF(M27="Borderline",1,0)))) -> 3 | P27: =N27*O27 -> 6 | Q27: Art.2 - Indici antropometrici | R27: Descrive quanto il tronco si allontana dal cilindro per avvicinarsi al doppio cono. Normalizza la vita per peso e statura, quindi l'addome sporge al netto della corporatura.
A28: 24 | B28: Adiposita | C28: Percentuale di grasso corporeo | D28: Deurenberg: 1,2xBMI + 0,23xeta - 10,8xsesso - 5,4 | E28: =1.2*E21+0.23*'01 Input'!$B$7-10.8*IF('01 Input'!$B$8="M",1,0)-5.4 -> 24.630163 | F28: % | G28: 23 | H28: =IF(G28=0,"",(E28-G28)/ABS(G28)) -> 0.070876631 | I28: 8 | J28: 25 | K28: Alto | L28: =IF(J28=I28,"",(E28-I28)/(J28-I28)) -> 0.97824485 | M28: =IF(E28>J28,"Fuori (alto)",IF(E28<I28,"Fuori (basso)",IF(AND(K28<>"Informativo",OR(AND(OR(K28="Alto",K28="Bilaterale"),L28>0.8),AND(OR(K28="Basso",K28="Bilaterale"),L28<0.2))),"Borderline","Normale"))) -> Borderline | N28: 1 | O28: =IF(N28=0,0,IF(AND(E28>J28,OR(K28="Alto",K28="Bilaterale")),IF((E28-J28)/(J28-I28)>0.1,3,2),IF(AND(E28<I28,OR(K28="Basso",K28="Bilaterale")),IF((I28-E28)/(J28-I28)>0.1,3,2),IF(M28="Borderline",1,0)))) -> 1 | P28: =N28*O28 -> 1 | Q28: Art.2 - Indici antropometrici | R28: Formula non dichiarata dalla fonte: Deurenberg e la piu probabile ma restituisce 24,6 contro i 23 pubblicati. Stima derivata dal BMI, quindi eredita il difetto del BMI di non distinguere i tessuti.
A29: 25 | B29: Adiposita | C29: Body Adiposity Index (BAI) | D29: fianchi / altezza_m^1,5 - 18 | E29: ='01 Input'!$B$14/(('01 Input'!$B$12/100)^1.5)-18 -> 25.568853 | F29: % | G29: 25 | H29: =IF(G29=0,"",(E29-G29)/ABS(G29)) -> 0.022754123 | I29: 8 | J29: 23 | K29: Alto | L29: =IF(J29=I29,"",(E29-I29)/(J29-I29)) -> 1.1712569 | M29: =IF(E29>J29,"Fuori (alto)",IF(E29<I29,"Fuori (basso)",IF(AND(K29<>"Informativo",OR(AND(OR(K29="Alto",K29="Bilaterale"),L29>0.8),AND(OR(K29="Basso",K29="Bilaterale"),L29<0.2))),"Borderline","Normale"))) -> Fuori (alto) | N29: 2 | O29: =IF(N29=0,0,IF(AND(E29>J29,OR(K29="Alto",K29="Bilaterale")),IF((E29-J29)/(J29-I29)>0.1,3,2),IF(AND(E29<I29,OR(K29="Basso",K29="Bilaterale")),IF((I29-E29)/(J29-I29)>0.1,3,2),IF(M29="Borderline",1,0)))) -> 3 | P29: =N29*O29 -> 6 | Q29: Art.2 - Indici antropometrici | R29: Ricava l'adiposita da fianchi e altezza senza mai usare il peso. Quando due indici di adiposita divergono sulla stessa persona vince quello che non usa il peso, perche e il peso a mascherare la ricomposizione corporea.
A30: 26 | B30: Adiposita | C30: Body Roundness Index (BRI) | D30: 364,2 - 365,5 x RADQ(1 - ((vita/2pi)/(0,5xH))^2) | E30: =364.2-365.5*SQRT(1-((('01 Input'!$B$13/100)/(2*PI()))/(0.5*('01 Input'!$B$12/100)))^2) -> 4.5004604 | F30: - | G30: 4.5 | H30: =IF(G30=0,"",(E30-G30)/ABS(G30)) -> 0.00010232089 | I30: 1 | J30: 4.71 | K30: Alto | L30: =IF(J30=I30,"",(E30-I30)/(J30-I30)) -> 0.94352034 | M30: =IF(E30>J30,"Fuori (alto)",IF(E30<I30,"Fuori (basso)",IF(AND(K30<>"Informativo",OR(AND(OR(K30="Alto",K30="Bilaterale"),L30>0.8),AND(OR(K30="Basso",K30="Bilaterale"),L30<0.2))),"Borderline","Normale"))) -> Borderline | N30: 1 | O30: =IF(N30=0,0,IF(AND(E30>J30,OR(K30="Alto",K30="Bilaterale")),IF((E30-J30)/(J30-I30)>0.1,3,2),IF(AND(E30<I30,OR(K30="Basso",K30="Bilaterale")),IF((I30-E30)/(J30-I30)>0.1,3,2),IF(M30="Borderline",1,0)))) -> 1 | P30: =N30*O30 -> 1 | Q30: Art.2 - Indici antropometrici | R30: Uno dei due indici assolti del gruppo, e va registrato con onestà. Dentro il riferimento, ma nell'ultimo 10% dell'intervallo.
A31: 27 | B31: Adiposita | C31: Abdominal Volume Index (AVI) | D31: (2 x vita^2 + 0,7 x (vita-fianchi)^2) / 1000 | E31: =(2*'01 Input'!$B$13^2+0.7*('01 Input'!$B$13-'01 Input'!$B$14)^2)/1000 -> 18.8243 | F31: - | G31: 11.89 | H31: =IF(G31=0,"",(E31-G31)/ABS(G31)) -> 0.58320437 | I31: 0 | J31: 24.5 | K31: Alto | L31: =IF(J31=I31,"",(E31-I31)/(J31-I31)) -> 0.76833878 | M31: =IF(E31>J31,"Fuori (alto)",IF(E31<I31,"Fuori (basso)",IF(AND(K31<>"Informativo",OR(AND(OR(K31="Alto",K31="Bilaterale"),L31>0.8),AND(OR(K31="Basso",K31="Bilaterale"),L31<0.2))),"Borderline","Normale"))) -> Normale | N31: 1 | O31: =IF(N31=0,0,IF(AND(E31>J31,OR(K31="Alto",K31="Bilaterale")),IF((E31-J31)/(J31-I31)>0.1,3,2),IF(AND(E31<I31,OR(K31="Basso",K31="Bilaterale")),IF((I31-E31)/(J31-I31)>0.1,3,2),IF(M31="Borderline",1,0)))) -> 0 | P31: =N31*O31 -> 0 | Q31: Art.2 - Indici antropometrici | R31: NON RIPRODUCIBILE: la formula standard restituisce 18,82 contro gli 11,89 pubblicati. L'esito resta 'dentro il riferimento' con entrambi i valori, quindi la conclusione non cambia, ma il numero non torna. Vedi foglio 08.
A32: 28 | B32: Ibridi | C32: Lipid Accumulation Product (LAP) | D32: (vita - 65) x trigliceridi in mmol/L | E32: =('01 Input'!$B$13-65)*('01 Input'!$B$30/88.57) -> 53.47183 | F32: - | G32: 53.5 | H32: =IF(G32=0,"",(E32-G32)/ABS(G32)) -> -0.00052653849 | I32: 0 | J32: 26.7 | K32: Alto | L32: =IF(J32=I32,"",(E32-I32)/(J32-I32)) -> 2.0026903 | M32: =IF(E32>J32,"Fuori (alto)",IF(E32<I32,"Fuori (basso)",IF(AND(K32<>"Informativo",OR(AND(OR(K32="Alto",K32="Bilaterale"),L32>0.8),AND(OR(K32="Basso",K32="Bilaterale"),L32<0.2))),"Borderline","Normale"))) -> Fuori (alto) | N32: 3 | O32: =IF(N32=0,0,IF(AND(E32>J32,OR(K32="Alto",K32="Bilaterale")),IF((E32-J32)/(J32-I32)>0.1,3,2),IF(AND(E32<I32,OR(K32="Basso",K32="Bilaterale")),IF((I32-E32)/(J32-I32)>0.1,3,2),IF(M32="Borderline",1,0)))) -> 3 | P32: =N32*O32 -> 9 | Q32: Art.2 - Indici antropometrici | R32: Il doppio esatto del cut-off. Riconosce il rischio cardiovascolare meglio del BMI (PMID 16150143). Nasce dall'incrocio fra una vita di 97 cm e trigliceridi che presi da soli nessun laboratorio segnalerebbe.
A33: 29 | B33: Ibridi | C33: Cardiometabolic Index (CMI) | D33: (vita/altezza) x (TG/HDL) in mmol/L | E33: =('01 Input'!$B$13/'01 Input'!$B$12)*(('01 Input'!$B$30/88.57)/('01 Input'!$B$29/38.67)) -> 0.87859327 | F33: - | G33: 0.88 | H33: =IF(G33=0,"",(E33-G33)/ABS(G33)) -> -0.0015985573 | I33: 0 | J33: 0.39 | K33: Alto | L33: =IF(J33=I33,"",(E33-I33)/(J33-I33)) -> 2.2528033 | M33: =IF(E33>J33,"Fuori (alto)",IF(E33<I33,"Fuori (basso)",IF(AND(K33<>"Informativo",OR(AND(OR(K33="Alto",K33="Bilaterale"),L33>0.8),AND(OR(K33="Basso",K33="Bilaterale"),L33<0.2))),"Borderline","Normale"))) -> Fuori (alto) | N33: 2 | O33: =IF(N33=0,0,IF(AND(E33>J33,OR(K33="Alto",K33="Bilaterale")),IF((E33-J33)/(J33-I33)>0.1,3,2),IF(AND(E33<I33,OR(K33="Basso",K33="Bilaterale")),IF((I33-E33)/(J33-I33)>0.1,3,2),IF(M33="Borderline",1,0)))) -> 3 | P33: =N33*O33 -> 6 | Q33: Art.2 - Indici antropometrici | R33: Piu del doppio del cut-off. Buon discriminatore di diabete e disglicemia (PMID 25199852). Va calcolato in mmol/L: usando i mg/dL verrebbe 2,01, un numero che non ha piu alcun rapporto con la soglia.
A34: 30 | B34: Ibridi | C34: Visceral Adiposity Index (VAI) | D34: (vita/(39,68+1,88xBMI)) x (TG/1,03) x (1,31/HDL), mmol/L | E34: =('01 Input'!$B$13/(39.68+1.88*E21))*(('01 Input'!$B$30/88.57)/1.03)*(1.31/('01 Input'!$B$29/38.67)) -> 2.2706085 | F34: - | G34: 2.29 | H34: =IF(G34=0,"",(E34-G34)/ABS(G34)) -> -0.0084678898 | I34: 0 | J34: 1.92 | K34: Alto | L34: =IF(J34=I34,"",(E34-I34)/(J34-I34)) -> 1.1826086 | M34: =IF(E34>J34,"Fuori (alto)",IF(E34<I34,"Fuori (basso)",IF(AND(K34<>"Informativo",OR(AND(OR(K34="Alto",K34="Bilaterale"),L34>0.8),AND(OR(K34="Basso",K34="Bilaterale"),L34<0.2))),"Borderline","Normale"))) -> Fuori (alto) | N34: 3 | O34: =IF(N34=0,0,IF(AND(E34>J34,OR(K34="Alto",K34="Bilaterale")),IF((E34-J34)/(J34-I34)>0.1,3,2),IF(AND(E34<I34,OR(K34="Basso",K34="Bilaterale")),IF((I34-E34)/(J34-I34)>0.1,3,2),IF(M34="Borderline",1,0)))) -> 3 | P34: =N34*O34 -> 9 | Q34: Art.2 - Indici antropometrici | R34: Marcatore della FUNZIONE del tessuto adiposo viscerale, non della sua quantita (PMID 20067971). Il referto commenta: disfunzione moderata del tessuto adiposo, resistenza insulinica presente. E l'indice che rivela il BMI usato internamente dal referto.
A35: 31 | B35: Mortalita | C35: A Body Shape Index (ABSI) - z-score | D35: z da tabelle NHANES per eta e sesso | E35: ='01 Input'!$B$55 -> 1.52 | F35: z | G35: 1.52 | H35: =IF(G35=0,"",(E35-G35)/ABS(G35)) -> 0 | I35: -0.272 | J35: 0.228 | K35: Alto | L35: =IF(J35=I35,"",(E35-I35)/(J35-I35)) -> 3.584 | M35: =IF(E35>J35,"Fuori (alto)",IF(E35<I35,"Fuori (basso)",IF(AND(K35<>"Informativo",OR(AND(OR(K35="Alto",K35="Bilaterale"),L35>0.8),AND(OR(K35="Basso",K35="Bilaterale"),L35<0.2))),"Borderline","Normale"))) -> Fuori (alto) | N35: 3 | O35: =IF(N35=0,0,IF(AND(E35>J35,OR(K35="Alto",K35="Bilaterale")),IF((E35-J35)/(J35-I35)>0.1,3,2),IF(AND(E35<I35,OR(K35="Basso",K35="Bilaterale")),IF((I35-E35)/(J35-I35)>0.1,3,2),IF(M35="Borderline",1,0)))) -> 3 | P35: =N35*O35 -> 9 | Q35: Art.2 - Indici antropometrici | R35: L'unico indice il cui commento non ammette diplomazia: rischio di mortalita molto alto. Costruito su 14.105 adulti NHANES per isolare la forma corporea depurata da peso e BMI, con aumento quasi esponenziale della mortalita (PMID 22815707). E l'indice che un normopeso non si aspetta mai di trovare alterato. Il valore grezzo di ABSI e ricalcolabile (0,0873), lo z-score no: le tabelle di riferimento non sono pubblicate.
A36: 32 | B36: Muscolo | C36: Circonferenza polpaccio corretta per BMI | D36: CC - correzione categoriale EWGSOP2 | E36: ='01 Input'!$B$15-IF(E21<18.5,-4,IF(E21<25,0,IF(E21<30,3,7))) -> 34 | F36: cm | G36: 33.5 | H36: =IF(G36=0,"",(E36-G36)/ABS(G36)) -> 0.014925373 | I36: 34 | J36: 45 | K36: Basso | L36: =IF(J36=I36,"",(E36-I36)/(J36-I36)) -> 0 | M36: =IF(E36>J36,"Fuori (alto)",IF(E36<I36,"Fuori (basso)",IF(AND(K36<>"Informativo",OR(AND(OR(K36="Alto",K36="Bilaterale"),L36>0.8),AND(OR(K36="Basso",K36="Bilaterale"),L36<0.2))),"Borderline","Normale"))) -> Borderline | N36: 3 | O36: =IF(N36=0,0,IF(AND(E36>J36,OR(K36="Alto",K36="Bilaterale")),IF((E36-J36)/(J36-I36)>0.1,3,2),IF(AND(E36<I36,OR(K36="Basso",K36="Bilaterale")),IF((I36-E36)/(J36-I36)>0.1,3,2),IF(M36="Borderline",1,0)))) -> 1 | P36: =N36*O36 -> 3 | Q36: Art.2 - Indici antropometrici | R36: Surrogato validato della massa muscolare appendicolare (PMID 30312372). La correzione applicata dal referto non e pubblicata: con quella categoriale EWGSOP2 il BMI del soggetto non comporta alcuna correzione e il valore resterebbe 34,0 cm, cioe ESATTAMENTE sulla soglia invece che sotto. La diagnosi di sarcopenia moderata dipende interamente da quei 5 millimetri non documentati.
A37: 33 | B37: Ferro circolante | C37: Sideremia | D37: misurata | E37: ='01 Input'!$B$33 -> 13.6 | F37: uM | G37: 13.6 | H37: =IF(G37=0,"",(E37-G37)/ABS(G37)) -> 0 | I37: 13 | J37: 27 | K37: Basso | L37: =IF(J37=I37,"",(E37-I37)/(J37-I37)) -> 0.042857143 | M37: =IF(E37>J37,"Fuori (alto)",IF(E37<I37,"Fuori (basso)",IF(AND(K37<>"Informativo",OR(AND(OR(K37="Alto",K37="Bilaterale"),L37>0.8),AND(OR(K37="Basso",K37="Bilaterale"),L37<0.2))),"Borderline","Normale"))) -> Borderline | N37: 2 | O37: =IF(N37=0,0,IF(AND(E37>J37,OR(K37="Alto",K37="Bilaterale")),IF((E37-J37)/(J37-I37)>0.1,3,2),IF(AND(E37<I37,OR(K37="Basso",K37="Bilaterale")),IF((I37-E37)/(J37-I37)>0.1,3,2),IF(M37="Borderline",1,0)))) -> 1 | P37: =N37*O37 -> 2 | Q37: Art.3 - Profilo marziale | R37: Dentro l'intervallo per sei decimi di micromole: e il valore piu basso possibile senza essere segnalato. Ha un ritmo circadiano marcato, quindi un prelievo pomeridiano abbasserebbe la saturazione di diversi punti senza che le riserve siano cambiate.
A38: 34 | B38: Ferro circolante | C38: Sideremia aggiustata per infiammazione | D38: sideremia x fattore BRINDA | E38: ='01 Input'!$B$33*'01 Input'!$B$36 -> 17.10064 | F38: uM | G38: 17.1 | H38: =IF(G38=0,"",(E38-G38)/ABS(G38)) -> 3.7426901e-05 | I38: 15 | J38: 23 | K38: Basso | L38: =IF(J38=I38,"",(E38-I38)/(J38-I38)) -> 0.26258 | M38: =IF(E38>J38,"Fuori (alto)",IF(E38<I38,"Fuori (basso)",IF(AND(K38<>"Informativo",OR(AND(OR(K38="Alto",K38="Bilaterale"),L38>0.8),AND(OR(K38="Basso",K38="Bilaterale"),L38<0.2))),"Borderline","Normale"))) -> Normale | N38: 1 | O38: =IF(N38=0,0,IF(AND(E38>J38,OR(K38="Alto",K38="Bilaterale")),IF((E38-J38)/(J38-I38)>0.1,3,2),IF(AND(E38<I38,OR(K38="Basso",K38="Bilaterale")),IF((I38-E38)/(J38-I38)>0.1,3,2),IF(M38="Borderline",1,0)))) -> 0 | P38: =N38*O38 -> 0 | Q38: Art.3 - Profilo marziale | R38: La correzione per l'infiammazione alza il ferro circolante e abbassa la ferritina, cioe spinge le due grandezze in direzioni opposte. Il fattore non e pubblicato: e stato dedotto dal rapporto fra valore aggiustato e valore grezzo.
A39: 35 | B39: Trasporto | C39: Transferrina | D39: misurata | E39: ='01 Input'!$B$34 -> 39.2 | F39: uM | G39: 39.2 | H39: =IF(G39=0,"",(E39-G39)/ABS(G39)) -> 0 | I39: 25.1 | J39: 50.3 | K39: Alto | L39: =IF(J39=I39,"",(E39-I39)/(J39-I39)) -> 0.55952381 | M39: =IF(E39>J39,"Fuori (alto)",IF(E39<I39,"Fuori (basso)",IF(AND(K39<>"Informativo",OR(AND(OR(K39="Alto",K39="Bilaterale"),L39>0.8),AND(OR(K39="Basso",K39="Bilaterale"),L39<0.2))),"Borderline","Normale"))) -> Normale | N39: 1 | O39: =IF(N39=0,0,IF(AND(E39>J39,OR(K39="Alto",K39="Bilaterale")),IF((E39-J39)/(J39-I39)>0.1,3,2),IF(AND(E39<I39,OR(K39="Basso",K39="Bilaterale")),IF((I39-E39)/(J39-I39)>0.1,3,2),IF(M39="Borderline",1,0)))) -> 0 | P39: =N39*O39 -> 0 | Q39: Art.3 - Profilo marziale | R39: Il camion che trasporta il ferro. Il fegato ne produce di piu proprio quando il ferro scarseggia, quindi un valore alto e un segnale di carenza, non di abbondanza.
A40: 36 | B40: Trasporto | C40: TIBC (capacita totale legante) | D40: 2 x transferrina | E40: =2*E39 -> 78.4 | F40: uM | G40: 78.4 | H40: =IF(G40=0,"",(E40-G40)/ABS(G40)) -> 0 | I40: 45 | J40: 76 | K40: Alto | L40: =IF(J40=I40,"",(E40-I40)/(J40-I40)) -> 1.0774194 | M40: =IF(E40>J40,"Fuori (alto)",IF(E40<I40,"Fuori (basso)",IF(AND(K40<>"Informativo",OR(AND(OR(K40="Alto",K40="Bilaterale"),L40>0.8),AND(OR(K40="Basso",K40="Bilaterale"),L40<0.2))),"Borderline","Normale"))) -> Fuori (alto) | N40: 1 | O40: =IF(N40=0,0,IF(AND(E40>J40,OR(K40="Alto",K40="Bilaterale")),IF((E40-J40)/(J40-I40)>0.1,3,2),IF(AND(E40<I40,OR(K40="Basso",K40="Bilaterale")),IF((I40-E40)/(J40-I40)>0.1,3,2),IF(M40="Borderline",1,0)))) -> 2 | P40: =N40*O40 -> 2 | Q40: Art.3 - Profilo marziale | R40: Ogni molecola di transferrina lega due atomi di ferro: da qui il fattore 2, che riproduce esattamente il valore pubblicato. Oltre la finestra ottimale significa che circolano molti posti liberi sui camion.
A41: 37 | B41: Trasporto | C41: UIBC (capacita legante insatura) | D41: TIBC - sideremia | E41: =E40-E37 -> 64.8 | F41: uM | G41: 64.8 | H41: =IF(G41=0,"",(E41-G41)/ABS(G41)) -> 0 | I41: 22 | J41: 61 | K41: Alto | L41: =IF(J41=I41,"",(E41-I41)/(J41-I41)) -> 1.0974359 | M41: =IF(E41>J41,"Fuori (alto)",IF(E41<I41,"Fuori (basso)",IF(AND(K41<>"Informativo",OR(AND(OR(K41="Alto",K41="Bilaterale"),L41>0.8),AND(OR(K41="Basso",K41="Bilaterale"),L41<0.2))),"Borderline","Normale"))) -> Fuori (alto) | N41: 1 | O41: =IF(N41=0,0,IF(AND(E41>J41,OR(K41="Alto",K41="Bilaterale")),IF((E41-J41)/(J41-I41)>0.1,3,2),IF(AND(E41<I41,OR(K41="Basso",K41="Bilaterale")),IF((I41-E41)/(J41-I41)>0.1,3,2),IF(M41="Borderline",1,0)))) -> 2 | P41: =N41*O41 -> 2 | Q41: Art.3 - Profilo marziale | R41: I posti liberi effettivi. Conferma dall'altro lato quello che dice la saturazione: la capacita di trasporto c'e, il carico no.
...

Sheet 03 Formule
A1: 03 - Dizionario delle formule
A2: Le formule marcate 'Ricostruita' non sono scritte per esteso nelle fonti: sono state ricavate cercando l'espressione che riproduce il valore pubblicato dai dati grezzi noti.
A4: # | B4: Fonte | C4: Grandezza | D4: Formula | E4: Verifica sul caso | F4: Origine | G4: Nota metodologica
A5: 1 | B5: Art.1 | C5: Pressione arteriosa media | D5: MAP = DBP + 0,4 x (SBP - DBP) | E5: 84 + 0,4x44 = 101,6 -> 101 | F5: Ricostruita | G5: La formula classica (SBP + 2xDBP)/3 restituisce 98,7 e NON riproduce il valore pubblicato. Il coefficiente 0,4 al posto di 1/3 tiene conto dell'accorciamento della diastole. Chi ricalcola con la classica ottiene un Modified Shock Index di 0,83 invece di 0,81.
A6: 2 | B6: Art.1 | C6: Pressione di pulsazione | D6: PP = SBP - DBP | E6: 128 - 84 = 44 | F6: Esplicita | G6: Cresce quando l'aorta perde elasticita e smette di ammortizzare l'onda sistolica.
A7: 3 | B7: Art.1 | C7: FC massima - formula popolare | D7: FCmax = 220 - eta | E7: 220 - 50 = 170 | F7: Citata come errata | G7: Sottostima la FC massima negli adulti maturi. E la formula che fa sospettare un errore a chi verifica il referto.
A8: 4 | B8: Art.1 | C8: FC massima - Tanaka | D8: FCmax = 208 - 0,7 x eta | E8: 208 - 35 = 173 | F8: PMID 11153730 | G8: Meta-analisi su 351 studi e 18.712 soggetti. Migliora la stima ma resta lineare, quindi applica lo stesso decadimento a ogni eta.
A9: 5 | B9: Art.1 | C9: FC massima - modello del referto | D9: modello logistico sesso-specifico | E9: 175 (da referto) | F9: PMID 12752560 / 11722475 | G9: Tarato su cicloergometro fino a esaurimento. Decadimento non costante: 0,43 bpm/anno a 25 anni, 0,83 a 50, 1,35 a 75. Coefficienti non pubblicati.
A10: 6 | B10: Art.1 | C10: FC di riserva | D10: FCris = FCmax - FCriposo | E10: 175 - 82 = 93 | F10: Esplicita | G10: Migliora abbassando il basale, cioe senza che il cuore cambi davvero: e un artefatto da tenere presente.
A11: 7 | B11: Art.1 | C11: Modified Shock Index | D11: MSI = FCriposo / MAP | E11: 82 / 101 = 0,81 | F11: Esplicita | G11: La fonte segnala l'errore diffuso di usare la sistolica al denominatore: 82/128 darebbe 0,64.
A12: 8 | B12: Art.1 | C12: Prodotto cardiovascolare | D12: RPP = FCriposo x SBP | E12: 82 x 128 = 10.496 | F12: Esplicita / PMID 38453019 | G12: Rate pressure product, surrogato del consumo miocardico di ossigeno.
A13: 9 | B13: Art.1 | C13: Portata cardiaca | D13: CO = SV x FC | E13: 66 x 82 = 5.412 mL/min | F13: Esplicita | G13: Lo stesso output si ottiene con SV 80 mL e FC 68: la portata normale non distingue una pompa capiente lenta da una piccola veloce.
A14: 10 | B14: Art.1 | C14: Cardiac Index | D14: CI = CO / BSA | E14: 5,412 / 1,9 = 2,85 -> 2,8 | F14: Esplicita | G14: Portata indicizzata per superficie corporea.
A15: 11 | B15: Art.1 | C15: Left Cardiac Work Index | D15: LCWI = CI x MAP x 2,222 | E15: 2,8 x 101 x 2,222 = 628 (referto 627) | F15: Ricostruita | G15: La costante converte L/min x mmHg in milliwatt: 1 L/min = 1,6667e-5 m3/s e 1 mmHg = 133,322 Pa, prodotto 2,222 mW. Con il CI e la MAP non arrotondati si ottengono 643, circa il 2,6% sopra il pubblicato.
A16: 12 | B16: Art.1 | C16: Indice di rigidita arteriosa | D16: ASI = PP / MAP | E16: 44 / 101 = 0,436 -> 0,44 | F16: Ricostruita | G16: Il rapporto alternativo PP/SBP darebbe 0,34 e non riproduce il referto.
... A56: 52 | B56: Art.4 | C56: Ricostruzione dell'emocromo | D56: piastrine = AISI/SIRI; monociti = AISI/SII; linfociti = monociti/MLR; neutrofili = SIRI x linfociti / monociti | E56: P 272; M 0,662; L 1,741; N 5,868 | F56: Inversione degli indici | G56: L'articolo non pubblica i conteggi assoluti, ma il sistema di sei indici in quattro incognite e sovradeterminato e si risolve. La verifica incrociata restituisce SII, SIRI, AISI e MLR esatti, NLR entro lo 0,8% e PLR entro l'1,1%.

Sheet 04 Zone FC
A1: 04 - Zone di frequenza cardiaca
A2: Ricavate dalla FC massima del foglio 01. Le soglie si ottengono troncando all'intero la percentuale della FC massima.
A4: Zona | B4: Obiettivo | C4: % min | D4: % max | E4: Da (bpm) | F4: A (bpm) | G4: Nota
A5: 0 | B5: Riposo | C5: 0 | D5: 0.5 | E5: 0 | F5: =INT(C6*'01 Input'!$B$25)-1 -> 86 | G5: Zona in cui si trova il soggetto a riposo.
A6: 1 | B6: Attivita moderata | C6: 0.5 | D6: 0.6 | E6: =INT(C6*'01 Input'!$B$25) -> 87 | F6: =INT(C7*'01 Input'!$B$25)-1 -> 104 | G6: Il limite inferiore e il confine che il soggetto sfiora da fermo.
A7: 2 | B7: Controllo del peso | C7: 0.6 | D7: 0.7 | E7: =INT(C7*'01 Input'!$B$25) -> 105 | F7: =INT(C8*'01 Input'!$B$25)-1 -> 121
A8: 3 | B8: Aerobiosi | C8: 0.7 | D8: 0.8 | E8: =INT(C8*'01 Input'!$B$25) -> 122 | F8: =INT(C9*'01 Input'!$B$25)-1 -> 139
A9: 4 | B9: Anaerobiosi | C9: 0.8 | D9: 0.9 | E9: =INT(C9*'01 Input'!$B$25) -> 140 | F9: =INT(C10*'01 Input'!$B$25)-1 -> 156
A10: 5 | B10: Massimale | C10: 0.9 | D10: 1 | E10: =INT(C10*'01 Input'!$B$25) -> 157 | F10: ='01 Input'!$B$25 -> 175 | G10: Da leggere con la tolleranza del 90-110% sulla FC massima predetta.
B12: FC a riposo del soggetto | E12: ='01 Input'!$B$23 -> 82
B13: Soglia di uscita dalla zona 0 | E13: =E6 -> 87
B14: Margine residuo prima di uscire dal riposo | E14: =E13-E12 -> 5 | G14: Battiti che separano il soggetto, da fermo, dalla zona dell'attivita moderata.

Sheet 05 Evidenze
A1: 05 - Evidenze citate dalle fonti
A2: Ogni riga riporta la misura di rischio come pubblicata e la sua applicabilita al caso in esame.
A4: # | B4: Fonte | C4: PMID | D4: Studio / disegno | E4: Numerosita | F4: Esposizione | G4: Misura | H4: Esito | I4: Applicabilita al caso
A5: 1 | B5: Art.1 | C5: 26598376 | D5: Meta-analisi di 46 studi prospettici | E5: 1.246.203 soggetti / 78.349 decessi | F5: FC a riposo, per ogni +10 bpm | G5: RR 1,09 | H5: Mortalita totale | I5: Il soggetto e a 82 bpm: 17 bpm oltre la fascia di minimo, circa +16% di rischio relativo per estrapolazione.
A6: 2 | B6: Art.1 | C6: 26598376 | D6: Meta-analisi - analisi per categorie | E6: 1.246.203 soggetti | F6: FC a riposo > 80 bpm | G6: RR 1,45 | H6: Mortalita totale | I6: SOGLIA SUPERATA (82 bpm). E il salto di scala descritto dalla fonte.
A7: 3 | B7: Art.1 | C7: 26598376 | D7: Meta-analisi - analisi per categorie | E7: 1.246.203 soggetti | F7: FC a riposo > 80 bpm | G7: RR 1,33 | H7: Mortalita cardiovascolare | I7: Soglia superata.
A8: 4 | B8: Art.1 | C8: 11337213 | D8: Coorte giapponese, 18 anni | E8: 573 uomini, 40-64 anni | F8: FC > 90 vs 60-69 bpm | G8: RR 2,68 | H8: Mortalita | I8: Il minimo di mortalita cade fra 60 e 69 bpm e l'aumento comincia ben prima dei 90: il soggetto e nel tratto ascendente.
A9: 5 | B9: Art.1 | C9: 28067310 | D9: Coorte di Kailuan, 3 misurazioni in 4 anni | E9: 47.311 adulti | F9: FC >= 80 bpm in tutte e tre le misurazioni | G9: HR 1,86 | H9: Mortalita per ogni causa | I9: Lo studio piu pertinente perche misura la persistenza. Applicabile solo se il valore viene confermato nel tempo: servono misurazioni ripetute.
A10: 6 | B10: Art.1 | C10: 17446799 | D10: Coorte prospettica, 5 anni | E10: 1.910 uomini | F10: Riserva impegnata sotto l'80% | G10: HR 2,8 | H10: Mortalita cardiovascolare | I10: NON VALUTABILE: richiede un test da sforzo che il referto non contiene. E il principale accertamento mancante.
A11: 7 | B11: Art.1 | C11: 10353296 | D11: Revisione (Palatini) sull'ipertono simpatico | E11: - | F11: Tachicardia cronica | G11: - | H11: Meccanismo | I11: Doppio meccanismo: marcatore di iperattivita adrenergica e stimolo meccanico diretto, con stress di parete che favorisce la placca.
A12: 8 | B12: Art.1 | C12: 33793325 | D12: Revisione su Circulation Research | E12: - | F12: Pressione di pulsazione elevata | G12: - | H12: Invecchiamento vascolare | I12: La pulsatilita si scarica su cervello e rene e riduce la diastolica utile alla perfusione coronarica. Il soggetto e dentro il range.
A13: 9 | B13: Art.1 | C13: 38453019 | D13: Letteratura sul rate pressure product | E13: - | F13: Prodotto cardiovascolare | G13: - | H13: Consumo miocardico di O2 | I13: Valida il prodotto cardiovascolare come surrogato non invasivo del consumo miocardico di ossigeno.
A14: 10 | B14: Art.1 | C14: 35328926 | D14: Effetti acuti del fumo | E14: giovani normotesi | F14: Singola sigaretta | G14: - | H14: Aumento acuto di MAP e FC | I14: Effetto acuto: su un referto a riposo conta poco. Rileva cio che resta fra una sigaretta e l'altra.
A15: 11 | B15: Art.1 | C15: 8689656 | D15: Caso-controllo su variabilita RR | E15: 20 fumatori > 20 sig/die vs controlli | F15: Fumo abituale | G15: LF 70,6 vs 46,0; HF 22,1 vs 42,0 | H15: Assetto autonomico spostato | I15: APPLICABILE: il soggetto fuma 20 sigarette al giorno. Piu acceleratore simpatico, meno freno vagale. Parte dei battiti in eccesso viene da qui.
A16: 12 | B16: Art.1 | C16: 16029383 | D16: Studio su forti fumatori | E16: - | F16: Durata dell'abitudine | G16: - | H16: Calo della modulazione vagale | I16: APPLICABILE E PIU PERTINENTE: misura gli anni, non solo le sigarette. Il soggetto ne ha 30.
... A43: 39 | B43: Art.4 | C43: 12160596 | D43: Studio metodologico (Van Tiel) | E43: - | F43: VES | G43: - | H43: Limiti interpretativi | I43: Sostiene il ridimensionamento della VES come strumento per l'infiammazione cronica di basso grado.

Sheet 06 Rischio
A1: 06 - Valutazione della pericolosita
A2: Tre letture indipendenti: il punteggio strumentale dagli indici delle due fonti, i fattori anamnestici che i referti non contengono e il rischio relativo epidemiologico.
B4: A - PUNTEGGIO STRUMENTALE (59 indici, quattro fonti)
B5: Indici valutati in totale | C5: =COUNT('02 Indici'!$O$5:$O$63) -> 59 | G5: Righe presenti nel foglio 02.
B6: Indici normali | C6: =COUNTIF('02 Indici'!$M$5:$M$63,"Normale") -> 22
B7: Indici borderline (in zona di guardia) | C7: =COUNTIF('02 Indici'!$M$5:$M$63,"Borderline") -> 12 | G7: Dentro l'intervallo ma nell'ultimo 20% verso il lato critico. I referti li stampano come normali.
B8: Indici fuori intervallo | C8: =COUNTIF('02 Indici'!$M$5:$M$63,"Fuori (alto)")+COUNTIF('02 Indici'!$M$5:$M$63,"Fuori (basso)") -> 25
B9: di cui dall'articolo 1 (cardiologici) | C9: =COUNTIFS('02 Indici'!$Q$5:$Q$63,"Art.1*",'02 Indici'!$M$5:$M$63,"Fuori (alto)")+COUNTIFS('02 Indici'!$Q$5:$Q$63,"Art.1*",'02 Indici'!$M$5:$M$63,"Fuori (basso)") -> 1 | G9: La fonte dichiara 1 indice fuori range su 16.
B10: di cui dall'articolo 2 (antropometrici) | C10: =COUNTIFS('02 Indici'!$Q$5:$Q$63,"Art.2*",'02 Indici'!$M$5:$M$63,"Fuori (alto)")+COUNTIFS('02 Indici'!$Q$5:$Q$63,"Art.2*",'02 Indici'!$M$5:$M$63,"Fuori (basso)") -> 8 | G10: La fonte dichiara 6 indici oltre soglia su 12; applicando i cut-off delle sue stesse tabelle ne risultano 9. Vedi foglio 08.
B11: di cui dall'articolo 3 (profilo marziale) | C11: =COUNTIFS('02 Indici'!$Q$5:$Q$63,"Art.3*",'02 Indici'!$M$5:$M$63,"Fuori (alto)")+COUNTIFS('02 Indici'!$Q$5:$Q$63,"Art.3*",'02 Indici'!$M$5:$M$63,"Fuori (basso)") -> 6 | G11: La fonte dichiara 5 valori fuori dalle finestre ottimali su 11; applicando gli intervalli della sua stessa tabella ne risultano 6. Vedi foglio 08.
B12: di cui dall'articolo 4 (infiammatori) | C12: =COUNTIFS('02 Indici'!$Q$5:$Q$63,"Art.4*",'02 Indici'!$M$5:$M$63,"Fuori (alto)")+COUNTIFS('02 Indici'!$Q$5:$Q$63,"Art.4*",'02 Indici'!$M$5:$M$63,"Fuori (basso)") -> 10 | G12: La fonte dichiara 10 indici fuori riferimento su 16 e il conteggio coincide, ma il decimo (monociti/linfociti) sta esattamente sul limite: e il solo caso in cui la classificazione dipende dall'ultima cifra decimale.
B13: Punteggio ponderato ottenuto | C13: =SUM('02 Indici'!$P$5:$P$63) -> 170 | G13: Somma di peso clinico x punteggio 0-3.
B14: Punteggio massimo teorico | C14: =SUM('02 Indici'!$N$5:$N$63)*3 -> 273 | G14: Se ogni indice pesato fosse gravemente fuori range.
B15: COMPONENTE STRUMENTALE | C15: =IF(C14=0,0,C13/C14) -> 0.62271062 | G15: Quota del massimo teorico raggiunta.
B17: B - FATTORI ANAMNESTICI E PATTERN CHE I SINGOLI INDICI NON ESPRIMONO
B18: Fattore | C18: Presente | D18: Peso | E18: Punti | G18: Evidenza / nota
B19: Fumo attivo (>= 20 sigarette al giorno) | C19: =IF('01 Input'!$B$58>=20,1,0) -> 1 | D19: 3 | E19: =C19*D19 -> 3 | G19: PMID 8689656 - assetto autonomico spostato verso il simpatico anche a distanza dall'ultima sigaretta.
B20: Durata dell'abitudine tabagica >= 20 anni | C20: =IF('01 Input'!$B$59>=20,1,0) -> 1 | D20: 2 | E20: =C20*D20 -> 2 | G20: PMID 16029383 - la modulazione vagale cala al crescere degli anni, non solo delle sigarette.
B21: Fenotipo TOFI (normopeso con obesita centrale) | C21: =IF(AND('02 Indici'!$E21<25,'02 Indici'!$E$25>0.5),1,0) -> 1 | D21: 3 | E21: =C21*D21 -> 3 | G21: PMID 26551006 - calcolato dagli indici: BMI sotto 25 con vita oltre meta dell'altezza. La mortalita cardiovascolare supera quella dell'obeso con distribuzione periferica.
B22: Miosteatosi documentata | C22: ='01 Input'!$B$60 -> 1 | D22: 2 | E22: =C22*D22 -> 2 | G22: PMID 35227529 - infiltrazione adiposa del muscolo, non misurabile con l'antropometria di superficie. Un quadricipite infiltrato pesa uguale e lavora peggio.
B23: Sospetta apnea ostruttiva del sonno mai indagata | C23: ='01 Input'!$B$61 -> 1 | D23: 3 | E23: =C23*D23 -> 3 | G23: PMID 15301332 e 12609010 - il tono simpatico resta elevato anche in veglia. E il sospetto piu pesante proprio perche non e mai stato verificato.
B24: Sedentarieta | C24: ='01 Input'!$B$62 -> 1 | D24: 1 | E24: =C24*D24 -> 1 | G24: PMID 15793048 - l'esercizio supervisionato abbassa del 19% il prodotto cardiovascolare; la sua assenza toglie il principale fattore correttivo.
B25: Incremento ponderale > 5 kg dall'eta di 30 anni | C25: =IF('01 Input'!$B$11-'01 Input'!$B$17>5,1,0) -> 1 | D25: 1 | E25: =C25*D25 -> 1 | G25: Sei chili in vent'anni, trecento grammi l'anno: l'aumento piu banale del mondo. Sotto, circa dieci chili di grasso in piu e quattro di muscolo in meno.
B26: Pattern di eritropoiesi ferro-ristretta | C26: =IF(AND('02 Indici'!$E$42<20,'02 Indici'!$E$46>301.5),1,0) -> 1 | D26: 3 | E26: =C26*D26 -> 3 | G26: PMID 30401705 - calcolato dagli indici: saturazione sotto il 20% con depositi non esauriti. Il ferro c'e ma non arriva ai reticolociti. Nessuna singola riga del profilo marziale lo dice: emerge solo dalla combinazione.
