Workbook

Sheet 00 Istruzioni
A1: Scheda indici cardiometabolici - versione per inserimento dati
A2: Uomini e donne. Formule e soglie si adattano automaticamente al sesso indicato nel foglio 01.
A5: A COSA SERVE | B5: Calcolare da misure di routine una batteria di indici che i referti ordinari non riportano, e sintetizzarli in un punteggio unico di orientamento. Non richiede alcun esame aggiuntivo: tutto si ricava da metro da sarta, bilancia, pressione, emocromo e un profilo biochimico di base.
A7: COSA NON E | B7: Non e un dispositivo medico e non produce una diagnosi. Il punteggio e costruito su pesi scelti dall'autore del foglio e non e uno score clinico validato su una popolazione. Serve a mettere in fila dati che altrimenti restano sparsi, e a far emergere pattern che il singolo valore non mostra. La decisione clinica resta interamente al medico che ha in cura la persona.
A9: COME SI USA | B9: 1) Foglio '01 Paziente': compila le celle gialle. Le grigie sono facoltative. 2) Indica il sesso: cambia le formule di quattro indici e le soglie di quindici. 3) Foglio '04 Punteggio': leggi il punteggio globale, la copertura dei dati e le segnalazioni. 4) Foglio '03 Indici': il dettaglio, se serve capire da dove viene il punteggio. 5) Foglio '05 Follow-up': riporta i controlli successivi.
A11: DATI MANCANTI | B11: Un indice senza tutti i dati necessari mostra 'n.d.' e resta fuori dal punteggio: non viene stimato ne sostituito. Il foglio 04 indica la percentuale di copertura raggiunta. Sotto il 50% il punteggio va letto con molta cautela, perche misura solo la parte di quadro che i dati coprono.
A13: COSA NON SI PUO RICAVARE | B13: Alcuni dati non si ottengono per calcolo da altri, e il foglio non prova a inventarli: epcidina, contenuto emoglobinico reticolocitario, polisonnografia, test da sforzo, composizione corporea strumentale. Dove servirebbero, il foglio lo segnala come approfondimento da proporre, non come valore stimato.
A15: STIME E MISURE | B15: Tre valori del foglio sono stime di popolazione, non misure: la percentuale di grasso corporeo (derivata dal BMI), la frequenza cardiaca massima (derivata dall'eta) e il peso ideale. Portano un errore che nelle formule successive non e piu visibile. Vanno trattati come orientamento, non come dati del paziente.
A17: IL PUNTEGGIO | B17: Non e la somma dei singoli indici. Molti indici nascono dalla stessa misura, quindi sommarli conterebbe piu volte lo stesso dato: la circonferenza vita da sola alimenta sei indici, i linfociti sette. Il punteggio raggruppa gli indici per misura di origine, fa la media di ogni gruppo e somma i gruppi, cosi ogni misura pesa una volta sola. Il dettaglio e nel foglio 04.
A19: SOGLIE | B19: Tutte le soglie stanno nel foglio '02 Riferimenti' e sono modificabili. Se il tuo laboratorio usa intervalli diversi, cambiali li: il resto del foglio si adegua. Le soglie evidenziate in rosso sono quelle che differiscono fra uomo e donna.
A21: PRIVACY | B21: Il foglio non richiede dati identificativi. Se lo condividi, usa un codice al posto del nome.

Sheet Sheet

Sheet 01 Paziente
A1: 01 - Dati del paziente
A2: Compila le celle gialle. Le celle grigie sono facoltative: se le lasci vuote gli indici che le usano restituiscono 'n.d.' e non entrano nel punteggio.
A4: Dato | B4: Valore | C4: Unita | D4: Obbl. | E4: Nota
A5: IDENTIFICAZIONE
A6: Identificativo / codice paziente | D6: si | E6: Non inserire dati identificativi diretti se il file viene condiviso
A7: Data della valutazione | C7: gg/mm/aaaa | D7: si | E7: Serve al foglio 05 per il confronto nel tempo
A8: Sesso | B8: M | C8: M / F | D8: si | E8: DETERMINANTE: cambia formule e soglie di 14 indici. Menu a tendina
A9: Eta | C9: anni | D9: si
A11: ANTROPOMETRIA (metro da sarta e bilancia)
A12: Peso | C12: kg | D12: si
A13: Altezza | C13: cm | D13: si
A14: Circonferenza vita | C14: cm | D14: si | E14: A fine espirazione, a meta fra ultima costa e cresta iliaca. E la misura piu importante del foglio: da sola alimenta sei indici
A15: Circonferenza fianchi | C15: cm | D15: no | E15: Serve a vita/fianchi, BAI e volume addominale
A16: Circonferenza polpaccio | C16: cm | D16: no | E16: Surrogato della massa muscolare. Soglia 34 cm nell'uomo, 33 nella donna
A17: Circonferenza polso | C17: cm | D17: no | E17: Morfotipo. E l'unica misura che non cambia con dieta o allenamento
A19: PRESSIONE E CUORE
A20: Pressione sistolica | C20: mmHg | D20: no
A21: Pressione diastolica | C21: mmHg | D21: no
A22: Frequenza cardiaca a riposo | C22: bpm | D22: no | E22: Da misurare seduto, dopo cinque minuti di riposo
A23: Gittata sistolica | C23: mL | D23: no | E23: Solo se disponibile da ecocardiogramma o bioimpedenza cardiaca
A25: LIPIDI E METABOLISMO
A26: Colesterolo HDL | C26: mg/dL | D26: no | E26: Entra in quattro indici: e il denominatore piu ricorrente del foglio
A27: Trigliceridi | C27: mg/dL | D27: no
A28: Uricemia | C28: mg/dL | D28: no
A29: Omocisteina | C29: uM | D29: no
A31: ASSETTO MARZIALE
A32: Sideremia | C32: ug/dL | D32: no | E32: In unita convenzionali. Il prelievo va fatto al mattino a digiuno: il ferro ha un ritmo circadiano marcato
A33: Transferrina | C33: mg/dL | D33: no
A34: Ferritina | C34: ug/L | D34: no | E34: Non interpretabile da sola se c'e infiammazione: il foglio lo segnala
A36: INFIAMMAZIONE ED EMOCROMO
A37: Proteina C reattiva (PCR) | C37: mg/dL | D37: no | E37: Serve anche a stabilire se la ferritina e leggibile
A38: VES a 1 ora | C38: mm | D38: no
A39: Emoglobina | C39: g/dL | D39: no
A40: RDW | C40: % | D40: no
A41: Piastrine | C41: 10^9/L | D41: no
A42: Volume piastrinico medio (MPV) | C42: fL | D42: no
A43: Neutrofili (valore assoluto) | C43: 10^9/L | D43: no | E43: Valore ASSOLUTO, non percentuale
A44: Linfociti (valore assoluto) | C44: 10^9/L | D44: no | E44: Valore ASSOLUTO. Da solo alimenta sette indici
A45: Monociti (valore assoluto) | C45: 10^9/L | D45: no | E45: Valore ASSOLUTO
A47: FACOLTATIVI E ANAMNESTICI
...

Sheet 02 Riferimenti
A1: 02 - Soglie di riferimento per sesso
A2: Tutte le soglie sono modificabili: allineale al tuo laboratorio. Il foglio 03 le legge da qui in base al sesso indicato nel foglio 01.
A4: # | B4: Indice | C4: Min uomo | D4: Max uomo | E4: Min donna | F4: Max donna | G4: Direzione critica | H4: Peso | I4: Gruppo (ridondanza) | J4: Origine della soglia
A5: 1 | B5: Indice di massa corporea (BMI) | C5: 18.5 | D5: 24.9 | E5: 18.5 | F5: 24.9 | G5: Informativo | H5: 0 | I5: Corporatura | J5: OMS
A6: 2 | B6: Rapporto vita / altezza | C6: 0.3 | D6: 0.5 | E6: 0.3 | F6: 0.5 | G6: Alto | H6: 3 | I6: Vita | J6: Ashwell, PMID 22106927
A7: 3 | B7: Rapporto vita / fianchi | C7: 0.7 | D7: 0.9 | E7: 0.7 | F7: 0.85 | G7: Alto | H7: 2 | I7: Vita | J7: OMS
A8: 4 | B8: Conicity Index | C8: 1.1 | D8: 1.25 | E8: 1.05 | F8: 1.18 | G8: Alto | H8: 2 | I8: Vita | J8: Valdez
A9: 5 | B9: Percentuale di grasso corporeo (stima) | C9: 8 | D9: 25 | E9: 20 | F9: 36 | G9: Alto | H9: 1 | I9: Corporatura | J9: Deurenberg
A10: 6 | B10: Body Adiposity Index | C10: 8 | D10: 24 | E10: 21 | F10: 35 | G10: Alto | H10: 1 | I10: Fianchi | J10: Bergman
A11: 7 | B11: Body Roundness Index | C11: 1 | D11: 4.71 | E11: 1 | F11: 4.45 | G11: Alto | H11: 1 | I11: Vita | J11: Thomas
A12: 8 | B12: A Body Shape Index (grezzo) | C12: 0.07 | D12: 0.083 | E12: 0.068 | F12: 0.081 | G12: Alto | H12: 3 | I12: Vita | J12: Krakauer, PMID 22815707
A13: 9 | B13: Circonferenza polpaccio | C13: 34 | D13: 45 | E13: 33 | F13: 43 | G13: Basso | H13: 3 | I13: Muscolo | J13: EWGSOP2, PMID 30312372
A14: 10 | B14: Peso ideale (Lorenz) | C14: 40 | D14: 120 | E14: 40 | F14: 120 | G14: Informativo | H14: 0 | I14: Corporatura | J14: Lorenz
A15: 11 | B15: Morfotipo (altezza / polso) | C15: 9.6 | D15: 10.4 | E15: 10.1 | F15: 11 | G15: Informativo | H15: 0 | I15: Corporatura | J15: Convenzione antropometrica
A16: 12 | B16: Pressione sistolica | C16: 100 | D16: 129 | E16: 100 | F16: 129 | G16: Alto | H16: 1 | I16: Pressione | J16: ESC/ESH
... A47: 43 | B47: MPV / Piastrine | C47: 0 | D47: 6 | E47: 0 | F47: 6 | G47: Alto | H47: 1 | I47: Piastrine | J47: Korniluk, PMID 31148950
B49: Le soglie in rosso sono quelle che cambiano fra uomo e donna. Sono 20 indici su 43.
B50: A queste si aggiungono tre formule il cui calcolo stesso cambia per sesso: Visceral Adiposity Index (tutti i coefficienti), percentuale di grasso corporeo (termine sesso), peso ideale di Lorenz (denominatore) e frequenza cardiaca massima (Tanaka nell'uomo, Gulati nella donna).

Sheet 03 Indici
A1: 03 - Indici calcolati
A2: Tutto e calcolato dal foglio 01 con le soglie del foglio 02 secondo il sesso indicato. 'n.d.' significa che manca almeno un dato: quell'indice non entra nel punteggio.
A4: # | B4: Indice | C4: Valore | D4: Unita | E4: Min | F4: Max | G4: Stato | H4: Peso | I4: Punt. 0-3 | J4: Contrib. | K4: Gruppo | L4: Nota
A5: 1 | B5: Indice di massa corporea (BMI) | C5: ='01 Paziente'!$B$55 | D5: kg/m2 | E5: =IF('01 Paziente'!$B$8="M",'02 Riferimenti'!C5,'02 Riferimenti'!E5) -> 18.5 | F5: =IF('01 Paziente'!$B$8="M",'02 Riferimenti'!D5,'02 Riferimenti'!F5) -> 24.9 | G5: =IF(NOT(ISNUMBER(C5)),"n.d.",IF('02 Riferimenti'!$G$5="Informativo",IF(OR(C5>F5,C5<E5),"fuori fascia","in fascia"),IF(AND(C5>F5,OR('02 Riferimenti'!$G$5="Alto",'02 Riferimenti'!$G$5="Bilaterale")),"Fuori (alto)",IF(AND(C5<E5,OR('02 Riferimenti'!$G$5="Basso",'02 Riferimenti'!$G$5="Bilaterale")),"Fuori (basso)",IF(OR(C5>F5,C5<E5),"Fuori (non critico)",IF(AND('02 Riferimenti'!$G$5<>"Informativo",F5<>E5,OR(AND(OR('02 Riferimenti'!$G$5="Alto",'02 Riferimenti'!$G$5="Bilaterale"),(C5-E5)/(F5-E5)>0.8),AND(OR('02 Riferimenti'!$G$5="Basso",'02 Riferimenti'!$G$5="Bilaterale"),(C5-E5)/(F5-E5)<0.2))),"Borderline","Normale")))))) -> n.d. | H5: ='02 Riferimenti'!$H$5 -> 0 | I5: =IF(OR(G5="n.d.",H5=0),"",IF(AND(C5>F5,OR('02 Riferimenti'!$G$5="Alto",'02 Riferimenti'!$G$5="Bilaterale")),IF((C5-F5)/MAX(F5-E5,0.0001)>0.1,3,2),IF(AND(C5<E5,OR('02 Riferimenti'!$G$5="Basso",'02 Riferimenti'!$G$5="Bilaterale")),IF((E5-C5)/MAX(F5-E5,0.0001)>0.1,3,2),IF(G5="Borderline",1,0)))) | J5: =IF(I5="","",H5*I5) | K5: ='02 Riferimenti'!$I$5 -> Corporatura | L5: Peso 0 di proposito: e l'indice che assolve i corpi in disordine. Serve come contesto, non come giudizio.
A6: 2 | B6: Rapporto vita / altezza | C6: =IF(OR('01 Paziente'!$B$14="",'01 Paziente'!$B$13=""),"n.d.",'01 Paziente'!$B$14/'01 Paziente'!$B$13) -> n.d. | D6: - | E6: =IF('01 Paziente'!$B$8="M",'02 Riferimenti'!C6,'02 Riferimenti'!E6) -> 0.3 | F6: =IF('01 Paziente'!$B$8="M",'02 Riferimenti'!D6,'02 Riferimenti'!F6) -> 0.5 | G6: =IF(NOT(ISNUMBER(C6)),"n.d.",IF('02 Riferimenti'!$G$6="Informativo",IF(OR(C6>F6,C6<E6),"fuori fascia","in fascia"),IF(AND(C6>F6,OR('02 Riferimenti'!$G$6="Alto",'02 Riferimenti'!$G$6="Bilaterale")),"Fuori (alto)",IF(AND(C6<E6,OR('02 Riferimenti'!$G$6="Basso",'02 Riferimenti'!$G$6="Bilaterale")),"Fuori (basso)",IF(OR(C6>F6,C6<E6),"Fuori (non critico)",IF(AND('02 Riferimenti'!$G$6<>"Informativo",F6<>E6,OR(AND(OR('02 Riferimenti'!$G$6="Alto",'02 Riferimenti'!$G$6="Bilaterale"),(C6-E6)/(F6-E6)>0.8),AND(OR('02 Riferimenti'!$G$6="Basso",'02 Riferimenti'!$G$6="Bilaterale"),(C6-E6)/(F6-E6)<0.2))),"Borderline","Normale")))))) -> n.d. | H6: ='02 Riferimenti'!$H$6 -> 3 | I6: =IF(OR(G6="n.d.",H6=0),"",IF(AND(C6>F6,OR('02 Riferimenti'!$G$6="Alto",'02 Riferimenti'!$G$6="Bilaterale")),IF((C6-F6)/MAX(F6-E6,0.0001)>0.1,3,2),IF(AND(C6<E6,OR('02 Riferimenti'!$G$6="Basso",'02 Riferimenti'!$G$6="Bilaterale")),IF((E6-C6)/MAX(F6-E6,0.0001)>0.1,3,2),IF(G6="Borderline",1,0)))) | J6: =IF(I6="","",H6*I6) | K6: ='02 Riferimenti'!$I$6 -> Vita | L6: La regola aurea vale per entrambi i sessi: la vita deve misurare meno della meta dell'altezza. E il primo indice da guardare.
A7: 3 | B7: Rapporto vita / fianchi | C7: =IF(OR('01 Paziente'!$B$14="",'01 Paziente'!$B$15=""),"n.d.",'01 Paziente'!$B$14/'01 Paziente'!$B$15) -> n.d. | D7: - | E7: =IF('01 Paziente'!$B$8="M",'02 Riferimenti'!C7,'02 Riferimenti'!E7) -> 0.7 | F7: =IF('01 Paziente'!$B$8="M",'02 Riferimenti'!D7,'02 Riferimenti'!F7) -> 0.9 | G7: =IF(NOT(ISNUMBER(C7)),"n.d.",IF('02 Riferimenti'!$G$7="Informativo",IF(OR(C7>F7,C7<E7),"fuori fascia","in fascia"),IF(AND(C7>F7,OR('02 Riferimenti'!$G$7="Alto",'02 Riferimenti'!$G$7="Bilaterale")),"Fuori (alto)",IF(AND(C7<E7,OR('02 Riferimenti'!$G$7="Basso",'02 Riferimenti'!$G$7="Bilaterale")),"Fuori (basso)",IF(OR(C7>F7,C7<E7),"Fuori (non critico)",IF(AND('02 Riferimenti'!$G$7<>"Informativo",F7<>E7,OR(AND(OR('02 Riferimenti'!$G$7="Alto",'02 Riferimenti'!$G$7="Bilaterale"),(C7-E7)/(F7-E7)>0.8),AND(OR('02 Riferimenti'!$G$7="Basso",'02 Riferimenti'!$G$7="Bilaterale"),(C7-E7)/(F7-E7)<0.2))),"Borderline","Normale")))))) -> n.d. | H7: ='02 Riferimenti'!$H$7 -> 2 | I7: =IF(OR(G7="n.d.",H7=0),"",IF(AND(C7>F7,OR('02 Riferimenti'!$G$7="Alto",'02 Riferimenti'!$G$7="Bilaterale")),IF((C7-F7)/MAX(F7-E7,0.0001)>0.1,3,2),IF(AND(C7<E7,OR('02 Riferimenti'!$G$7="Basso",'02 Riferimenti'!$G$7="Bilaterale")),IF((E7-C7)/MAX(F7-E7,0.0001)>0.1,3,2),IF(G7="Borderline",1,0)))) | J7: =IF(I7="","",H7*I7) | K7: ='02 Riferimenti'!$I$7 -> Vita | L7: Soglia diversa per sesso: 0,90 nell'uomo, 0,85 nella donna.
A8: 4 | B8: Conicity Index | C8: =IF(OR('01 Paziente'!$B$14="",'01 Paziente'!$B$12="",'01 Paziente'!$B$13=""),"n.d.",('01 Paziente'!$B$14/100)/(0.109*SQRT('01 Paziente'!$B$12/('01 Paziente'!$B$13/100)))) -> n.d. | D8: - | E8: =IF('01 Paziente'!$B$8="M",'02 Riferimenti'!C8,'02 Riferimenti'!E8) -> 1.1 | F8: =IF('01 Paziente'!$B$8="M",'02 Riferimenti'!D8,'02 Riferimenti'!F8) -> 1.25 | G8: =IF(NOT(ISNUMBER(C8)),"n.d.",IF('02 Riferimenti'!$G$8="Informativo",IF(OR(C8>F8,C8<E8),"fuori fascia","in fascia"),IF(AND(C8>F8,OR('02 Riferimenti'!$G$8="Alto",'02 Riferimenti'!$G$8="Bilaterale")),"Fuori (alto)",IF(AND(C8<E8,OR('02 Riferimenti'!$G$8="Basso",'02 Riferimenti'!$G$8="Bilaterale")),"Fuori (basso)",IF(OR(C8>F8,C8<E8),"Fuori (non critico)",IF(AND('02 Riferimenti'!$G$8<>"Informativo",F8<>E8,OR(AND(OR('02 Riferimenti'!$G$8="Alto",'02 Riferimenti'!$G$8="Bilaterale"),(C8-E8)/(F8-E8)>0.8),AND(OR('02 Riferimenti'!$G$8="Basso",'02 Riferimenti'!$G$8="Bilaterale"),(C8-E8)/(F8-E8)<0.2))),"Borderline","Normale")))))) -> n.d. | H8: ='02 Riferimenti'!$H$8 -> 2 | I8: =IF(OR(G8="n.d.",H8=0),"",IF(AND(C8>F8,OR('02 Riferimenti'!$G$8="Alto",'02 Riferimenti'!$G$8="Bilaterale")),IF((C8-F8)/MAX(F8-E8,0.0001)>0.1,3,2),IF(AND(C8<E8,OR('02 Riferimenti'!$G$8="Basso",'02 Riferimenti'!$G$8="Bilaterale")),IF((E8-C8)/MAX(F8-E8,0.0001)>0.1,3,2),IF(G8="Borderline",1,0)))) | J8: =IF(I8="","",H8*I8) | K8: ='02 Riferimenti'!$I$8 -> Vita | L8: Quanto il tronco si allontana dal cilindro. Soglia piu bassa nella donna.
A9: 5 | B9: Percentuale di grasso corporeo (stima) | C9: =IF(OR('01 Paziente'!$B$55="",'01 Paziente'!$B$9=""),"n.d.",1.2*'01 Paziente'!$B$55+0.23*'01 Paziente'!$B$9-10.8*'01 Paziente'!$B$58-5.4) -> n.d. | D9: % | E9: =IF('01 Paziente'!$B$8="M",'02 Riferimenti'!C9,'02 Riferimenti'!E9) -> 8 | F9: =IF('01 Paziente'!$B$8="M",'02 Riferimenti'!D9,'02 Riferimenti'!F9) -> 25 | G9: =IF(NOT(ISNUMBER(C9)),"n.d.",IF('02 Riferimenti'!$G$9="Informativo",IF(OR(C9>F9,C9<E9),"fuori fascia","in fascia"),IF(AND(C9>F9,OR('02 Riferimenti'!$G$9="Alto",'02 Riferimenti'!$G$9="Bilaterale")),"Fuori (alto)",IF(AND(C9<E9,OR('02 Riferimenti'!$G$9="Basso",'02 Riferimenti'!$G$9="Bilaterale")),"Fuori (basso)",IF(OR(C9>F9,C9<E9),"Fuori (non critico)",IF(AND('02 Riferimenti'!$G$9<>"Informativo",F9<>E9,OR(AND(OR('02 Riferimenti'!$G$9="Alto",'02 Riferimenti'!$G$9="Bilaterale"),(C9-E9)/(F9-E9)>0.8),AND(OR('02 Riferimenti'!$G$9="Basso",'02 Riferimenti'!$G$9="Bilaterale"),(C9-E9)/(F9-E9)<0.2))),"Borderline","Normale")))))) -> n.d. | H9: ='02 Riferimenti'!$H$9 -> 1 | I9: =IF(OR(G9="n.d.",H9=0),"",IF(AND(C9>F9,OR('02 Riferimenti'!$G$9="Alto",'02 Riferimenti'!$G$9="Bilaterale")),IF((C9-F9)/MAX(F9-E9,0.0001)>0.1,3,2),IF(AND(C9<E9,OR('02 Riferimenti'!$G$9="Basso",'02 Riferimenti'!$G$9="Bilaterale")),IF((E9-C9)/MAX(F9-E9,0.0001)>0.1,3,2),IF(G9="Borderline",1,0)))) | J9: =IF(I9="","",H9*I9) | K9: ='02 Riferimenti'!$I$9 -> Corporatura | L9: STIMA derivata dal BMI, con errore di alcuni punti percentuali. La formula ha un termine per il sesso e le soglie sono molto diverse fra uomo e donna.
A10: 6 | B10: Body Adiposity Index | C10: =IF(OR('01 Paziente'!$B$15="",'01 Paziente'!$B$13=""),"n.d.",'01 Paziente'!$B$15/(('01 Paziente'!$B$13/100)^1.5)-18) -> n.d. | D10: % | E10: =IF('01 Paziente'!$B$8="M",'02 Riferimenti'!C10,'02 Riferimenti'!E10) -> 8 | F10: =IF('01 Paziente'!$B$8="M",'02 Riferimenti'!D10,'02 Riferimenti'!F10) -> 24 | G10: =IF(NOT(ISNUMBER(C10)),"n.d.",IF('02 Riferimenti'!$G$10="Informativo",IF(OR(C10>F10,C10<E10),"fuori fascia","in fascia"),IF(AND(C10>F10,OR('02 Riferimenti'!$G$10="Alto",'02 Riferimenti'!$G$10="Bilaterale")),"Fuori (alto)",IF(AND(C10<E10,OR('02 Riferimenti'!$G$10="Basso",'02 Riferimenti'!$G$10="Bilaterale")),"Fuori (basso)",IF(OR(C10>F10,C10<E10),"Fuori (non critico)",IF(AND('02 Riferimenti'!$G$10<>"Informativo",F10<>E10,OR(AND(OR('02 Riferimenti'!$G$10="Alto",'02 Riferimenti'!$G$10="Bilaterale"),(C10-E10)/(F10-E10)>0.8),AND(OR('02 Riferimenti'!$G$10="Basso",'02 Riferimenti'!$G$10="Bilaterale"),(C10-E10)/(F10-E10)<0.2))),"Borderline","Normale")))))) -> n.d. | H10: ='02 Riferimenti'!$H$10 -> 1 | I10: =IF(OR(G10="n.d.",H10=0),"",IF(AND(C10>F10,OR('02 Riferimenti'!$G$10="Alto",'02 Riferimenti'!$G$10="Bilaterale")),IF((C10-F10)/MAX(F10-E10,0.0001)>0.1,3,2),IF(AND(C10<E10,OR('02 Riferimenti'!$G$10="Basso",'02 Riferimenti'!$G$10="Bilaterale")),IF((E10-C10)/MAX(F10-E10,0.0001)>0.1,3,2),IF(G10="Borderline",1,0)))) | J10: =IF(I10="","",H10*I10) | K10: ='02 Riferimenti'!$I$10 -> Fianchi | L10: Peso ridotto a 1: sovrastima nei soggetti magri con fianchi normali. Non usa mai il peso: utile quando diverge dalla stima basata sul BMI. Fasce di normalita molto diverse per sesso.
A11: 7 | B11: Body Roundness Index | C11: =IF(OR('01 Paziente'!$B$14="",'01 Paziente'!$B$13=""),"n.d.",364.2-365.5*SQRT(1-((('01 Paziente'!$B$14/100)/(2*PI()))/(0.5*('01 Paziente'!$B$13/100)))^2)) -> n.d. | D11: - | E11: =IF('01 Paziente'!$B$8="M",'02 Riferimenti'!C11,'02 Riferimenti'!E11) -> 1 | F11: =IF('01 Paziente'!$B$8="M",'02 Riferimenti'!D11,'02 Riferimenti'!F11) -> 4.71 | G11: =IF(NOT(ISNUMBER(C11)),"n.d.",IF('02 Riferimenti'!$G$11="Informativo",IF(OR(C11>F11,C11<E11),"fuori fascia","in fascia"),IF(AND(C11>F11,OR('02 Riferimenti'!$G$11="Alto",'02 Riferimenti'!$G$11="Bilaterale")),"Fuori (alto)",IF(AND(C11<E11,OR('02 Riferimenti'!$G$11="Basso",'02 Riferimenti'!$G$11="Bilaterale")),"Fuori (basso)",IF(OR(C11>F11,C11<E11),"Fuori (non critico)",IF(AND('02 Riferimenti'!$G$11<>"Informativo",F11<>E11,OR(AND(OR('02 Riferimenti'!$G$11="Alto",'02 Riferimenti'!$G$11="Bilaterale"),(C11-E11)/(F11-E11)>0.8),AND(OR('02 Riferimenti'!$G$11="Basso",'02 Riferimenti'!$G$11="Bilaterale"),(C11-E11)/(F11-E11)<0.2))),"Borderline","Normale")))))) -> n.d. | H11: ='02 Riferimenti'!$H$11 -> 1 | I11: =IF(OR(G11="n.d.",H11=0),"",IF(AND(C11>F11,OR('02 Riferimenti'!$G$11="Alto",'02 Riferimenti'!$G$11="Bilaterale")),IF((C11-F11)/MAX(F11-E11,0.0001)>0.1,3,2),IF(AND(C11<E11,OR('02 Riferimenti'!$G$11="Basso",'02 Riferimenti'!$G$11="Bilaterale")),IF((E11-C11)/MAX(F11-E11,0.0001)>0.1,3,2),IF(G11="Borderline",1,0)))) | J11: =IF(I11="","",H11*I11) | K11: ='02 Riferimenti'!$I$11 -> Vita | L11: Soglia indicativa, piu bassa nella donna.
A12: 8 | B12: A Body Shape Index (grezzo) | C12: =IF(OR('01 Paziente'!$B$14="",'01 Paziente'!$B$55="",'01 Paziente'!$B$13=""),"n.d.",('01 Paziente'!$B$14/100)/(('01 Paziente'!$B$55^(2/3))*SQRT('01 Paziente'!$B$13/100))) -> n.d. | D12: - | E12: =IF('01 Paziente'!$B$8="M",'02 Riferimenti'!C12,'02 Riferimenti'!E12) -> 0.07 | F12: =IF('01 Paziente'!$B$8="M",'02 Riferimenti'!D12,'02 Riferimenti'!F12) -> 0.083 | G12: =IF(NOT(ISNUMBER(C12)),"n.d.",IF('02 Riferimenti'!$G$12="Informativo",IF(OR(C12>F12,C12<E12),"fuori fascia","in fascia"),IF(AND(C12>F12,OR('02 Riferimenti'!$G$12="Alto",'02 Riferimenti'!$G$12="Bilaterale")),"Fuori (alto)",IF(AND(C12<E12,OR('02 Riferimenti'!$G$12="Basso",'02 Riferimenti'!$G$12="Bilaterale")),"Fuori (basso)",IF(OR(C12>F12,C12<E12),"Fuori (non critico)",IF(AND('02 Riferimenti'!$G$12<>"Informativo",F12<>E12,OR(AND(OR('02 Riferimenti'!$G$12="Alto",'02 Riferimenti'!$G$12="Bilaterale"),(C12-E12)/(F12-E12)>0.8),AND(OR('02 Riferimenti'!$G$12="Basso",'02 Riferimenti'!$G$12="Bilaterale"),(C12-E12)/(F12-E12)<0.2))),"Borderline","Normale")))))) -> n.d. | H12: ='02 Riferimenti'!$H$12 -> 3 | I12: =IF(OR(G12="n.d.",H12=0),"",IF(AND(C12>F12,OR('02 Riferimenti'!$G$12="Alto",'02 Riferimenti'!$G$12="Bilaterale")),IF((C12-F12)/MAX(F12-E12,0.0001)>0.1,3,2),IF(AND(C12<E12,OR('02 Riferimenti'!$G$12="Basso",'02 Riferimenti'!$G$12="Bilaterale")),IF((E12-C12)/MAX(F12-E12,0.0001)>0.1,3,2),IF(G12="Borderline",1,0)))) | J12: =IF(I12="","",H12*I12) | K12: ='02 Riferimenti'!$I$12 -> Vita | L12: Isola la forma corporea depurata da peso e BMI. Se il laboratorio fornisce lo z-score, inseriscilo nel foglio 01: e piu preciso di questa soglia grezza.
A13: 9 | B13: Circonferenza polpaccio | C13: =IF('01 Paziente'!$B$16="","n.d.",'01 Paziente'!$B$16) -> n.d. | D13: cm | E13: =IF('01 Paziente'!$B$8="M",'02 Riferimenti'!C13,'02 Riferimenti'!E13) -> 34 | F13: =IF('01 Paziente'!$B$8="M",'02 Riferimenti'!D13,'02 Riferimenti'!F13) -> 45 | G13: =IF(NOT(ISNUMBER(C13)),"n.d.",IF('02 Riferimenti'!$G$13="Informativo",IF(OR(C13>F13,C13<E13),"fuori fascia","in fascia"),IF(AND(C13>F13,OR('02 Riferimenti'!$G$13="Alto",'02 Riferimenti'!$G$13="Bilaterale")),"Fuori (alto)",IF(AND(C13<E13,OR('02 Riferimenti'!$G$13="Basso",'02 Riferimenti'!$G$13="Bilaterale")),"Fuori (basso)",IF(OR(C13>F13,C13<E13),"Fuori (non critico)",IF(AND('02 Riferimenti'!$G$13<>"Informativo",F13<>E13,OR(AND(OR('02 Riferimenti'!$G$13="Alto",'02 Riferimenti'!$G$13="Bilaterale"),(C13-E13)/(F13-E13)>0.8),AND(OR('02 Riferimenti'!$G$13="Basso",'02 Riferimenti'!$G$13="Bilaterale"),(C13-E13)/(F13-E13)<0.2))),"Borderline","Normale")))))) -> n.d. | H13: ='02 Riferimenti'!$H$13 -> 3 | I13: =IF(OR(G13="n.d.",H13=0),"",IF(AND(C13>F13,OR('02 Riferimenti'!$G$13="Alto",'02 Riferimenti'!$G$13="Bilaterale")),IF((C13-F13)/MAX(F13-E13,0.0001)>0.1,3,2),IF(AND(C13<E13,OR('02 Riferimenti'!$G$13="Basso",'02 Riferimenti'!$G$13="Bilaterale")),IF((E13-C13)/MAX(F13-E13,0.0001)>0.1,3,2),IF(G13="Borderline",1,0)))) | J13: =IF(I13="","",H13*I13) | K13: ='02 Riferimenti'!$I$13 -> Muscolo | L13: Soglia 34 cm nell'uomo, 33 nella donna. Nessuna correzione per BMI: quella usata da alcuni referti non e pubblicata e sposta la diagnosi di sarcopenia.
A14: 10 | B14: Peso ideale (Lorenz) | C14: =IF(OR('01 Paziente'!$B$13="",'01 Paziente'!$B$8=""),"n.d.",'01 Paziente'!$B$13-100-('01 Paziente'!$B$13-150)/IF('01 Paziente'!$B$8="M",4,2)) -> n.d. | D14: kg | E14: =IF('01 Paziente'!$B$8="M",'02 Riferimenti'!C14,'02 Riferimenti'!E14) -> 40 | F14: =IF('01 Paziente'!$B$8="M",'02 Riferimenti'!D14,'02 Riferimenti'!F14) -> 120 | G14: =IF(NOT(ISNUMBER(C14)),"n.d.",IF('02 Riferimenti'!$G$14="Informativo",IF(OR(C14>F14,C14<E14),"fuori fascia","in fascia"),IF(AND(C14>F14,OR('02 Riferimenti'!$G$14="Alto",'02 Riferimenti'!$G$14="Bilaterale")),"Fuori (alto)",IF(AND(C14<E14,OR('02 Riferimenti'!$G$14="Basso",'02 Riferimenti'!$G$14="Bilaterale")),"Fuori (basso)",IF(OR(C14>F14,C14<E14),"Fuori (non critico)",IF(AND('02 Riferimenti'!$G$14<>"Informativo",F14<>E14,OR(AND(OR('02 Riferimenti'!$G$14="Alto",'02 Riferimenti'!$G$14="Bilaterale"),(C14-E14)/(F14-E14)>0.8),AND(OR('02 Riferimenti'!$G$14="Basso",'02 Riferimenti'!$G$14="Bilaterale"),(C14-E14)/(F14-E14)<0.2))),"Borderline","Normale")))))) -> n.d. | H14: ='02 Riferimenti'!$H$14 -> 0 | I14: =IF(OR(G14="n.d.",H14=0),"",IF(AND(C14>F14,OR('02 Riferimenti'!$G$14="Alto",'02 Riferimenti'!$G$14="Bilaterale")),IF((C14-F14)/MAX(F14-E14,0.0001)>0.1,3,2),IF(AND(C14<E14,OR('02 Riferimenti'!$G$14="Basso",'02 Riferimenti'!$G$14="Bilaterale")),IF((E14-C14)/MAX(F14-E14,0.0001)>0.1,3,2),IF(G14="Borderline",1,0)))) | J14: =IF(I14="","",H14*I14) | K14: ='02 Riferimenti'!$I$14 -> Corporatura | L14: Denominatore diverso per sesso. Indicativo: e una convenzione, non una misura.
A15: 11 | B15: Morfotipo (altezza / polso) | C15: =IF(OR('01 Paziente'!$B$13="",'01 Paziente'!$B$17=""),"n.d.",'01 Paziente'!$B$13/'01 Paziente'!$B$17) -> n.d. | D15: - | E15: =IF('01 Paziente'!$B$8="M",'02 Riferimenti'!C15,'02 Riferimenti'!E15) -> 9.6 | F15: =IF('01 Paziente'!$B$8="M",'02 Riferimenti'!D15,'02 Riferimenti'!F15) -> 10.4 | G15: =IF(NOT(ISNUMBER(C15)),"n.d.",IF('02 Riferimenti'!$G$15="Informativo",IF(OR(C15>F15,C15<E15),"fuori fascia","in fascia"),IF(AND(C15>F15,OR('02 Riferimenti'!$G$15="Alto",'02 Riferimenti'!$G$15="Bilaterale")),"Fuori (alto)",IF(AND(C15<E15,OR('02 Riferimenti'!$G$15="Basso",'02 Riferimenti'!$G$15="Bilaterale")),"Fuori (basso)",IF(OR(C15>F15,C15<E15),"Fuori (non critico)",IF(AND('02 Riferimenti'!$G$15<>"Informativo",F15<>E15,OR(AND(OR('02 Riferimenti'!$G$15="Alto",'02 Riferimenti'!$G$15="Bilaterale"),(C15-E15)/(F15-E15)>0.8),AND(OR('02 Riferimenti'!$G$15="Basso",'02 Riferimenti'!$G$15="Bilaterale"),(C15-E15)/(F15-E15)<0.2))),"Borderline","Normale")))))) -> n.d. | H15: ='02 Riferimenti'!$H$15 -> 0 | I15: =IF(OR(G15="n.d.",H15=0),"",IF(AND(C15>F15,OR('02 Riferimenti'!$G$15="Alto",'02 Riferimenti'!$G$15="Bilaterale")),IF((C15-F15)/MAX(F15-E15,0.0001)>0.1,3,2),IF(AND(C15<E15,OR('02 Riferimenti'!$G$15="Basso",'02 Riferimenti'!$G$15="Bilaterale")),IF((E15-C15)/MAX(F15-E15,0.0001)>0.1,3,2),IF(G15="Borderline",1,0)))) | J15: =IF(I15="","",H15*I15) | K15: ='02 Riferimenti'!$I$15 -> Corporatura | L15: Fasce diverse per sesso. Dentro la fascia = normolineo; sotto = brevilineo; sopra = longilineo.
A16: 12 | B16: Pressione sistolica | C16: =IF('01 Paziente'!$B$20="","n.d.",'01 Paziente'!$B$20) -> n.d. | D16: mmHg | E16: =IF('01 Paziente'!$B$8="M",'02 Riferimenti'!C16,'02 Riferimenti'!E16) -> 100 | F16: =IF('01 Paziente'!$B$8="M",'02 Riferimenti'!D16,'02 Riferimenti'!F16) -> 129 | G16: =IF(NOT(ISNUMBER(C16)),"n.d.",IF('02 Riferimenti'!$G$16="Informativo",IF(OR(C16>F16,C16<E16),"fuori fascia","in fascia"),IF(AND(C16>F16,OR('02 Riferimenti'!$G$16="Alto",'02 Riferimenti'!$G$16="Bilaterale")),"Fuori (alto)",IF(AND(C16<E16,OR('02 Riferimenti'!$G$16="Basso",'02 Riferimenti'!$G$16="Bilaterale")),"Fuori (basso)",IF(OR(C16>F16,C16<E16),"Fuori (non critico)",IF(AND('02 Riferimenti'!$G$16<>"Informativo",F16<>E16,OR(AND(OR('02 Riferimenti'!$G$16="Alto",'02 Riferimenti'!$G$16="Bilaterale"),(C16-E16)/(F16-E16)>0.8),AND(OR('02 Riferimenti'!$G$16="Basso",'02 Riferimenti'!$G$16="Bilaterale"),(C16-E16)/(F16-E16)<0.2))),"Borderline","Normale")))))) -> n.d. | H16: ='02 Riferimenti'!$H$16 -> 1 | I16: =IF(OR(G16="n.d.",H16=0),"",IF(AND(C16>F16,OR('02 Riferimenti'!$G$16="Alto",'02 Riferimenti'!$G$16="Bilaterale")),IF((C16-F16)/MAX(F16-E16,0.0001)>0.1,3,2),IF(AND(C16<E16,OR('02 Riferimenti'!$G$16="Basso",'02 Riferimenti'!$G$16="Bilaterale")),IF((E16-C16)/MAX(F16-E16,0.0001)>0.1,3,2),IF(G16="Borderline",1,0)))) | J16: =IF(I16="","",H16*I16) | K16: ='02 Riferimenti'!$I$16 -> Pressione
A17: 13 | B17: Pressione diastolica | C17: =IF('01 Paziente'!$B$21="","n.d.",'01 Paziente'!$B$21) -> n.d. | D17: mmHg | E17: =IF('01 Paziente'!$B$8="M",'02 Riferimenti'!C17,'02 Riferimenti'!E17) -> 60 | F17: =IF('01 Paziente'!$B$8="M",'02 Riferimenti'!D17,'02 Riferimenti'!F17) -> 84 | G17: =IF(NOT(ISNUMBER(C17)),"n.d.",IF('02 Riferimenti'!$G$17="Informativo",IF(OR(C17>F17,C17<E17),"fuori fascia","in fascia"),IF(AND(C17>F17,OR('02 Riferimenti'!$G$17="Alto",'02 Riferimenti'!$G$17="Bilaterale")),"Fuori (alto)",IF(AND(C17<E17,OR('02 Riferimenti'!$G$17="Basso",'02 Riferimenti'!$G$17="Bilaterale")),"Fuori (basso)",IF(OR(C17>F17,C17<E17),"Fuori (non critico)",IF(AND('02 Riferimenti'!$G$17<>"Informativo",F17<>E17,OR(AND(OR('02 Riferimenti'!$G$17="Alto",'02 Riferimenti'!$G$17="Bilaterale"),(C17-E17)/(F17-E17)>0.8),AND(OR('02 Riferimenti'!$G$17="Basso",'02 Riferimenti'!$G$17="Bilaterale"),(C17-E17)/(F17-E17)<0.2))),"Borderline","Normale")))))) -> n.d. | H17: ='02 Riferimenti'!$H$17 -> 1 | I17: =IF(OR(G17="n.d.",H17=0),"",IF(AND(C17>F17,OR('02 Riferimenti'!$G$17="Alto",'02 Riferimenti'!$G$17="Bilaterale")),IF((C17-F17)/MAX(F17-E17,0.0001)>0.1,3,2),IF(AND(C17<E17,OR('02 Riferimenti'!$G$17="Basso",'02 Riferimenti'!$G$17="Bilaterale")),IF((E17-C17)/MAX(F17-E17,0.0001)>0.1,3,2),IF(G17="Borderline",1,0)))) | J17: =IF(I17="","",H17*I17) | K17: ='02 Riferimenti'!$I$17 -> Pressione
A18: 14 | B18: Pressione arteriosa media | C18: =IF(OR('01 Paziente'!$B$20="",'01 Paziente'!$B$21=""),"n.d.",('01 Paziente'!$B$20+2*'01 Paziente'!$B$21)/3) -> n.d. | D18: mmHg | E18: =IF('01 Paziente'!$B$8="M",'02 Riferimenti'!C18,'02 Riferimenti'!E18) -> 70 | F18: =IF('01 Paziente'!$B$8="M",'02 Riferimenti'!D18,'02 Riferimenti'!F18) -> 105 | G18: =IF(NOT(ISNUMBER(C18)),"n.d.",IF('02 Riferimenti'!$G$18="Informativo",IF(OR(C18>F18,C18<E18),"fuori fascia","in fascia"),IF(AND(C18>F18,OR('02 Riferimenti'!$G$18="Alto",'02 Riferimenti'!$G$18="Bilaterale")),"Fuori (alto)",IF(AND(C18<E18,OR('02 Riferimenti'!$G$18="Basso",'02 Riferimenti'!$G$18="Bilaterale")),"Fuori (basso)",IF(OR(C18>F18,C18<E18),"Fuori (non critico)",IF(AND('02 Riferimenti'!$G$18<>"Informativo",F18<>E18,OR(AND(OR('02 Riferimenti'!$G$18="Alto",'02 Riferimenti'!$G$18="Bilaterale"),(C18-E18)/(F18-E18)>0.8),AND(OR('02 Riferimenti'!$G$18="Basso",'02 Riferimenti'!$G$18="Bilaterale"),(C18-E18)/(F18-E18)<0.2))),"Borderline","Normale")))))) -> n.d. | H18: ='02 Riferimenti'!$H$18 -> 1 | I18: =IF(OR(G18="n.d.",H18=0),"",IF(AND(C18>F18,OR('02 Riferimenti'!$G$18="Alto",'02 Riferimenti'!$G$18="Bilaterale")),IF((C18-F18)/MAX(F18-E18,0.0001)>0.1,3,2),IF(AND(C18<E18,OR('02 Riferimenti'!$G$18="Basso",'02 Riferimenti'!$G$18="Bilaterale")),IF((E18-C18)/MAX(F18-E18,0.0001)>0.1,3,2),IF(G18="Borderline",1,0)))) | J18: =IF(I18="","",H18*I18) | K18: ='02 Riferimenti'!$I$18 -> Pressione | L18: Qui si usa la formula classica (SBP+2xDBP)/3. Alcuni referti usano DBP+0,4xPP, che da un valore piu alto: se confronti con un referto, verifica quale delle due ha usato.
A19: 15 | B19: Pressione di pulsazione | C19: =IF(OR('01 Paziente'!$B$20="",'01 Paziente'!$B$21=""),"n.d.",'01 Paziente'!$B$20-'01 Paziente'!$B$21) -> n.d. | D19: mmHg | E19: =IF('01 Paziente'!$B$8="M",'02 Riferimenti'!C19,'02 Riferimenti'!E19) -> 30 | F19: =IF('01 Paziente'!$B$8="M",'02 Riferimenti'!D19,'02 Riferimenti'!F19) -> 55 | G19: =IF(NOT(ISNUMBER(C19)),"n.d.",IF('02 Riferimenti'!$G$19="Informativo",IF(OR(C19>F19,C19<E19),"fuori fascia","in fascia"),IF(AND(C19>F19,OR('02 Riferimenti'!$G$19="Alto",'02 Riferimenti'!$G$19="Bilaterale")),"Fuori (alto)",IF(AND(C19<E19,OR('02 Riferimenti'!$G$19="Basso",'02 Riferimenti'!$G$19="Bilaterale")),"Fuori (basso)",IF(OR(C19>F19,C19<E19),"Fuori (non critico)",IF(AND('02 Riferimenti'!$G$19<>"Informativo",F19<>E19,OR(AND(OR('02 Riferimenti'!$G$19="Alto",'02 Riferimenti'!$G$19="Bilaterale"),(C19-E19)/(F19-E19)>0.8),AND(OR('02 Riferimenti'!$G$19="Basso",'02 Riferimenti'!$G$19="Bilaterale"),(C19-E19)/(F19-E19)<0.2))),"Borderline","Normale")))))) -> n.d. | H19: ='02 Riferimenti'!$H$19 -> 2 | I19: =IF(OR(G19="n.d.",H19=0),"",IF(AND(C19>F19,OR('02 Riferimenti'!$G$19="Alto",'02 Riferimenti'!$G$19="Bilaterale")),IF((C19-F19)/MAX(F19-E19,0.0001)>0.1,3,2),IF(AND(C19<E19,OR('02 Riferimenti'!$G$19="Basso",'02 Riferimenti'!$G$19="Bilaterale")),IF((E19-C19)/MAX(F19-E19,0.0001)>0.1,3,2),IF(G19="Borderline",1,0)))) | J19: =IF(I19="","",H19*I19) | K19: ='02 Riferimenti'!$I$19 -> Pressione | L19: Marcatore di rigidita dei grossi vasi e di invecchiamento vascolare.
A20: 16 | B20: Frequenza cardiaca a riposo | C20: =IF('01 Paziente'!$B$22="","n.d.",'01 Paziente'!$B$22) -> n.d. | D20: bpm | E20: =IF('01 Paziente'!$B$8="M",'02 Riferimenti'!C20,'02 Riferimenti'!E20) -> 50 | F20: =IF('01 Paziente'!$B$8="M",'02 Riferimenti'!D20,'02 Riferimenti'!F20) -> 76 | G20: =IF(NOT(ISNUMBER(C20)),"n.d.",IF('02 Riferimenti'!$G$20="Informativo",IF(OR(C20>F20,C20<E20),"fuori fascia","in fascia"),IF(AND(C20>F20,OR('02 Riferimenti'!$G$20="Alto",'02 Riferimenti'!$G$20="Bilaterale")),"Fuori (alto)",IF(AND(C20<E20,OR('02 Riferimenti'!$G$20="Basso",'02 Riferimenti'!$G$20="Bilaterale")),"Fuori (basso)",IF(OR(C20>F20,C20<E20),"Fuori (non critico)",IF(AND('02 Riferimenti'!$G$20<>"Informativo",F20<>E20,OR(AND(OR('02 Riferimenti'!$G$20="Alto",'02 Riferimenti'!$G$20="Bilaterale"),(C20-E20)/(F20-E20)>0.8),AND(OR('02 Riferimenti'!$G$20="Basso",'02 Riferimenti'!$G$20="Bilaterale"),(C20-E20)/(F20-E20)<0.2))),"Borderline","Normale")))))) -> n.d. | H20: ='02 Riferimenti'!$H$20 -> 3 | I20: =IF(OR(G20="n.d.",H20=0),"",IF(AND(C20>F20,OR('02 Riferimenti'!$G$20="Alto",'02 Riferimenti'!$G$20="Bilaterale")),IF((C20-F20)/MAX(F20-E20,0.0001)>0.1,3,2),IF(AND(C20<E20,OR('02 Riferimenti'!$G$20="Basso",'02 Riferimenti'!$G$20="Bilaterale")),IF((E20-C20)/MAX(F20-E20,0.0001)>0.1,3,2),IF(G20="Borderline",1,0)))) | J20: =IF(I20="","",H20*I20) | K20: ='02 Riferimenti'!$I$20 -> Frequenza | L20: Sopra 80 bpm il rischio cambia scala. Soglia leggermente piu alta nella donna.
A21: 17 | B21: Frequenza cardiaca di riserva | C21: =IF(OR('01 Paziente'!$B$22="",'01 Paziente'!$B$57=""),"n.d.",'01 Paziente'!$B$57-'01 Paziente'!$B$22) -> n.d. | D21: bpm | E21: =IF('01 Paziente'!$B$8="M",'02 Riferimenti'!C21,'02 Riferimenti'!E21) -> 70 | F21: =IF('01 Paziente'!$B$8="M",'02 Riferimenti'!D21,'02 Riferimenti'!F21) -> 130 | G21: =IF(NOT(ISNUMBER(C21)),"n.d.",IF('02 Riferimenti'!$G$21="Informativo",IF(OR(C21>F21,C21<E21),"fuori fascia","in fascia"),IF(AND(C21>F21,OR('02 Riferimenti'!$G$21="Alto",'02 Riferimenti'!$G$21="Bilaterale")),"Fuori (alto)",IF(AND(C21<E21,OR('02 Riferimenti'!$G$21="Basso",'02 Riferimenti'!$G$21="Bilaterale")),"Fuori (basso)",IF(OR(C21>F21,C21<E21),"Fuori (non critico)",IF(AND('02 Riferimenti'!$G$21<>"Informativo",F21<>E21,OR(AND(OR('02 Riferimenti'!$G$21="Alto",'02 Riferimenti'!$G$21="Bilaterale"),(C21-E21)/(F21-E21)>0.8),AND(OR('02 Riferimenti'!$G$21="Basso",'02 Riferimenti'!$G$21="Bilaterale"),(C21-E21)/(F21-E21)<0.2))),"Borderline","Normale")))))) -> n.d. | H21: ='02 Riferimenti'!$H$21 -> 1 | I21: =IF(OR(G21="n.d.",H21=0),"",IF(AND(C21>F21,OR('02 Riferimenti'!$G$21="Alto",'02 Riferimenti'!$G$21="Bilaterale")),IF((C21-F21)/MAX(F21-E21,0.0001)>0.1,3,2),IF(AND(C21<E21,OR('02 Riferimenti'!$G$21="Basso",'02 Riferimenti'!$G$21="Bilaterale")),IF((E21-C21)/MAX(F21-E21,0.0001)>0.1,3,2),IF(G21="Borderline",1,0)))) | J21: =IF(I21="","",H21*I21) | K21: ='02 Riferimenti'!$I$21 -> Frequenza | L21: Attenzione all'artefatto: migliora abbassando il basale, senza che il cuore cambi.
A22: 18 | B22: Modified Shock Index | C22: =IF(OR('01 Paziente'!$B$22="",'01 Paziente'!$B$20="",'01 Paziente'!$B$21=""),"n.d.",'01 Paziente'!$B$22/(('01 Paziente'!$B$20+2*'01 Paziente'!$B$21)/3)) -> n.d. | D22: - | E22: =IF('01 Paziente'!$B$8="M",'02 Riferimenti'!C22,'02 Riferimenti'!E22) -> 0.7 | F22: =IF('01 Paziente'!$B$8="M",'02 Riferimenti'!D22,'02 Riferimenti'!F22) -> 0.99 | G22: =IF(NOT(ISNUMBER(C22)),"n.d.",IF('02 Riferimenti'!$G$22="Informativo",IF(OR(C22>F22,C22<E22),"fuori fascia","in fascia"),IF(AND(C22>F22,OR('02 Riferimenti'!$G$22="Alto",'02 Riferimenti'!$G$22="Bilaterale")),"Fuori (alto)",IF(AND(C22<E22,OR('02 Riferimenti'!$G$22="Basso",'02 Riferimenti'!$G$22="Bilaterale")),"Fuori (basso)",IF(OR(C22>F22,C22<E22),"Fuori (non critico)",IF(AND('02 Riferimenti'!$G$22<>"Informativo",F22<>E22,OR(AND(OR('02 Riferimenti'!$G$22="Alto",'02 Riferimenti'!$G$22="Bilaterale"),(C22-E22)/(F22-E22)>0.8),AND(OR('02 Riferimenti'!$G$22="Basso",'02 Riferimenti'!$G$22="Bilaterale"),(C22-E22)/(F22-E22)<0.2))),"Borderline","Normale")))))) -> n.d. | H22: ='02 Riferimenti'!$H$22 -> 1 | I22: =IF(OR(G22="n.d.",H22=0),"",IF(AND(C22>F22,OR('02 Riferimenti'!$G$22="Alto",'02 Riferimenti'!$G$22="Bilaterale")),IF((C22-F22)/MAX(F22-E22,0.0001)>0.1,3,2),IF(AND(C22<E22,OR('02 Riferimenti'!$G$22="Basso",'02 Riferimenti'!$G$22="Bilaterale")),IF((E22-C22)/MAX(F22-E22,0.0001)>0.1,3,2),IF(G22="Borderline",1,0)))) | J22: =IF(I22="","",H22*I22) | K22: ='02 Riferimenti'!$I$22 -> Frequenza | L22: Va calcolato sulla pressione MEDIA, non sulla sistolica.
A23: 19 | B23: Prodotto cardiovascolare | C23: =IF(OR('01 Paziente'!$B$22="",'01 Paziente'!$B$20=""),"n.d.",'01 Paziente'!$B$22*'01 Paziente'!$B$20) -> n.d. | D23: bpm*mmHg | E23: =IF('01 Paziente'!$B$8="M",'02 Riferimenti'!C23,'02 Riferimenti'!E23) -> 6000 | F23: =IF('01 Paziente'!$B$8="M",'02 Riferimenti'!D23,'02 Riferimenti'!F23) -> 12000 | G23: =IF(NOT(ISNUMBER(C23)),"n.d.",IF('02 Riferimenti'!$G$23="Informativo",IF(OR(C23>F23,C23<E23),"fuori fascia","in fascia"),IF(AND(C23>F23,OR('02 Riferimenti'!$G$23="Alto",'02 Riferimenti'!$G$23="Bilaterale")),"Fuori (alto)",IF(AND(C23<E23,OR('02 Riferimenti'!$G$23="Basso",'02 Riferimenti'!$G$23="Bilaterale")),"Fuori (basso)",IF(OR(C23>F23,C23<E23),"Fuori (non critico)",IF(AND('02 Riferimenti'!$G$23<>"Informativo",F23<>E23,OR(AND(OR('02 Riferimenti'!$G$23="Alto",'02 Riferimenti'!$G$23="Bilaterale"),(C23-E23)/(F23-E23)>0.8),AND(OR('02 Riferimenti'!$G$23="Basso",'02 Riferimenti'!$G$23="Bilaterale"),(C23-E23)/(F23-E23)<0.2))),"Borderline","Normale")))))) -> n.d. | H23: ='02 Riferimenti'!$H$23 -> 2 | I23: =IF(OR(G23="n.d.",H23=0),"",IF(AND(C23>F23,OR('02 Riferimenti'!$G$23="Alto",'02 Riferimenti'!$G$23="Bilaterale")),IF((C23-F23)/MAX(F23-E23,0.0001)>0.1,3,2),IF(AND(C23<E23,OR('02 Riferimenti'!$G$23="Basso",'02 Riferimenti'!$G$23="Bilaterale")),IF((E23-C23)/MAX(F23-E23,0.0001)>0.1,3,2),IF(G23="Borderline",1,0)))) | J23: =IF(I23="","",H23*I23) | K23: ='02 Riferimenti'!$I$23 -> Frequenza | L23: Surrogato del consumo miocardico di ossigeno. Tre mesi di esercizio supervisionato lo abbassano di circa il 19%.
A24: 20 | B24: Portata cardiaca | C24: =IF(OR('01 Paziente'!$B$23="",'01 Paziente'!$B$22=""),"n.d.",'01 Paziente'!$B$23*'01 Paziente'!$B$22/1000) -> n.d. | D24: L/min | E24: =IF('01 Paziente'!$B$8="M",'02 Riferimenti'!C24,'02 Riferimenti'!E24) -> 3.5 | F24: =IF('01 Paziente'!$B$8="M",'02 Riferimenti'!D24,'02 Riferimenti'!F24) -> 6.9 | G24: =IF(NOT(ISNUMBER(C24)),"n.d.",IF('02 Riferimenti'!$G$24="Informativo",IF(OR(C24>F24,C24<E24),"fuori fascia","in fascia"),IF(AND(C24>F24,OR('02 Riferimenti'!$G$24="Alto",'02 Riferimenti'!$G$24="Bilaterale")),"Fuori (alto)",IF(AND(C24<E24,OR('02 Riferimenti'!$G$24="Basso",'02 Riferimenti'!$G$24="Bilaterale")),"Fuori (basso)",IF(OR(C24>F24,C24<E24),"Fuori (non critico)",IF(AND('02 Riferimenti'!$G$24<>"Informativo",F24<>E24,OR(AND(OR('02 Riferimenti'!$G$24="Alto",'02 Riferimenti'!$G$24="Bilaterale"),(C24-E24)/(F24-E24)>0.8),AND(OR('02 Riferimenti'!$G$24="Basso",'02 Riferimenti'!$G$24="Bilaterale"),(C24-E24)/(F24-E24)<0.2))),"Borderline","Normale")))))) -> n.d. | H24: ='02 Riferimenti'!$H$24 -> 1 | I24: =IF(OR(G24="n.d.",H24=0),"",IF(AND(C24>F24,OR('02 Riferimenti'!$G$24="Alto",'02 Riferimenti'!$G$24="Bilaterale")),IF((C24-F24)/MAX(F24-E24,0.0001)>0.1,3,2),IF(AND(C24<E24,OR('02 Riferimenti'!$G$24="Basso",'02 Riferimenti'!$G$24="Bilaterale")),IF((E24-C24)/MAX(F24-E24,0.0001)>0.1,3,2),IF(G24="Borderline",1,0)))) | J24: =IF(I24="","",H24*I24) | K24: ='02 Riferimenti'!$I$24 -> Pompa | L24: Richiede la gittata sistolica, spesso non disponibile.
A25: 21 | B25: Cardiac Index | C25: =IF(OR('01 Paziente'!$B$23="",'01 Paziente'!$B$22="",'01 Paziente'!$B$56=""),"n.d.",'01 Paziente'!$B$23*'01 Paziente'!$B$22/1000/'01 Paziente'!$B$56) -> n.d. | D25: L/min/m2 | E25: =IF('01 Paziente'!$B$8="M",'02 Riferimenti'!C25,'02 Riferimenti'!E25) -> 2.2 | F25: =IF('01 Paziente'!$B$8="M",'02 Riferimenti'!D25,'02 Riferimenti'!F25) -> 4 | G25: =IF(NOT(ISNUMBER(C25)),"n.d.",IF('02 Riferimenti'!$G$25="Informativo",IF(OR(C25>F25,C25<E25),"fuori fascia","in fascia"),IF(AND(C25>F25,OR('02 Riferimenti'!$G$25="Alto",'02 Riferimenti'!$G$25="Bilaterale")),"Fuori (alto)",IF(AND(C25<E25,OR('02 Riferimenti'!$G$25="Basso",'02 Riferimenti'!$G$25="Bilaterale")),"Fuori (basso)",IF(OR(C25>F25,C25<E25),"Fuori (non critico)",IF(AND('02 Riferimenti'!$G$25<>"Informativo",F25<>E25,OR(AND(OR('02 Riferimenti'!$G$25="Alto",'02 Riferimenti'!$G$25="Bilaterale"),(C25-E25)/(F25-E25)>0.8),AND(OR('02 Riferimenti'!$G$25="Basso",'02 Riferimenti'!$G$25="Bilaterale"),(C25-E25)/(F25-E25)<0.2))),"Borderline","Normale")))))) -> n.d. | H25: ='02 Riferimenti'!$H$25 -> 1 | I25: =IF(OR(G25="n.d.",H25=0),"",IF(AND(C25>F25,OR('02 Riferimenti'!$G$25="Alto",'02 Riferimenti'!$G$25="Bilaterale")),IF((C25-F25)/MAX(F25-E25,0.0001)>0.1,3,2),IF(AND(C25<E25,OR('02 Riferimenti'!$G$25="Basso",'02 Riferimenti'!$G$25="Bilaterale")),IF((E25-C25)/MAX(F25-E25,0.0001)>0.1,3,2),IF(G25="Borderline",1,0)))) | J25: =IF(I25="","",H25*I25) | K25: ='02 Riferimenti'!$I$25 -> Pompa
A26: 22 | B26: Colesterolo HDL | C26: =IF('01 Paziente'!$B$26="","n.d.",'01 Paziente'!$B$26) -> n.d. | D26: mg/dL | E26: =IF('01 Paziente'!$B$8="M",'02 Riferimenti'!C26,'02 Riferimenti'!E26) -> 40 | F26: =IF('01 Paziente'!$B$8="M",'02 Riferimenti'!D26,'02 Riferimenti'!F26) -> 90 | G26: =IF(NOT(ISNUMBER(C26)),"n.d.",IF('02 Riferimenti'!$G$26="Informativo",IF(OR(C26>F26,C26<E26),"fuori fascia","in fascia"),IF(AND(C26>F26,OR('02 Riferimenti'!$G$26="Alto",'02 Riferimenti'!$G$26="Bilaterale")),"Fuori (alto)",IF(AND(C26<E26,OR('02 Riferimenti'!$G$26="Basso",'02 Riferimenti'!$G$26="Bilaterale")),"Fuori (basso)",IF(OR(C26>F26,C26<E26),"Fuori (non critico)",IF(AND('02 Riferimenti'!$G$26<>"Informativo",F26<>E26,OR(AND(OR('02 Riferimenti'!$G$26="Alto",'02 Riferimenti'!$G$26="Bilaterale"),(C26-E26)/(F26-E26)>0.8),AND(OR('02 Riferimenti'!$G$26="Basso",'02 Riferimenti'!$G$26="Bilaterale"),(C26-E26)/(F26-E26)<0.2))),"Borderline","Normale")))))) -> n.d. | H26: ='02 Riferimenti'!$H$26 -> 2 | I26: =IF(OR(G26="n.d.",H26=0),"",IF(AND(C26>F26,OR('02 Riferimenti'!$G$26="Alto",'02 Riferimenti'!$G$26="Bilaterale")),IF((C26-F26)/MAX(F26-E26,0.0001)>0.1,3,2),IF(AND(C26<E26,OR('02 Riferimenti'!$G$26="Basso",'02 Riferimenti'!$G$26="Bilaterale")),IF((E26-C26)/MAX(F26-E26,0.0001)>0.1,3,2),IF(G26="Borderline",1,0)))) | J26: =IF(I26="","",H26*I26) | K26: ='02 Riferimenti'!$I$26 -> HDL | L26: Soglia 40 nell'uomo, 50 nella donna. Compare come denominatore in quattro indici di questo foglio.
A27: 23 | B27: Lipid Accumulation Product | C27: =IF(OR('01 Paziente'!$B$14="",'01 Paziente'!$B$27=""),"n.d.",('01 Paziente'!$B$14-IF('01 Paziente'!$B$8="M",65,58))*('01 Paziente'!$B$27/88.57)) -> n.d. | D27: - | E27: =IF('01 Paziente'!$B$8="M",'02 Riferimenti'!C27,'02 Riferimenti'!E27) -> 0 | F27: =IF('01 Paziente'!$B$8="M",'02 Riferimenti'!D27,'02 Riferimenti'!F27) -> 26.7 | G27: =IF(NOT(ISNUMBER(C27)),"n.d.",IF('02 Riferimenti'!$G$27="Informativo",IF(OR(C27>F27,C27<E27),"fuori fascia","in fascia"),IF(AND(C27>F27,OR('02 Riferimenti'!$G$27="Alto",'02 Riferimenti'!$G$27="Bilaterale")),"Fuori (alto)",IF(AND(C27<E27,OR('02 Riferimenti'!$G$27="Basso",'02 Riferimenti'!$G$27="Bilaterale")),"Fuori (basso)",IF(OR(C27>F27,C27<E27),"Fuori (non critico)",IF(AND('02 Riferimenti'!$G$27<>"Informativo",F27<>E27,OR(AND(OR('02 Riferimenti'!$G$27="Alto",'02 Riferimenti'!$G$27="Bilaterale"),(C27-E27)/(F27-E27)>0.8),AND(OR('02 Riferimenti'!$G$27="Basso",'02 Riferimenti'!$G$27="Bilaterale"),(C27-E27)/(F27-E27)<0.2))),"Borderline","Normale")))))) -> n.d. | H27: ='02 Riferimenti'!$H$27 -> 3 | I27: =IF(OR(G27="n.d.",H27=0),"",IF(AND(C27>F27,OR('02 Riferimenti'!$G$27="Alto",'02 Riferimenti'!$G$27="Bilaterale")),IF((C27-F27)/MAX(F27-E27,0.0001)>0.1,3,2),IF(AND(C27<E27,OR('02 Riferimenti'!$G$27="Basso",'02 Riferimenti'!$G$27="Bilaterale")),IF((E27-C27)/MAX(F27-E27,0.0001)>0.1,3,2),IF(G27="Borderline",1,0)))) | J27: =IF(I27="","",H27*I27) | K27: ='02 Riferimenti'!$I$27 -> Vita | L27: Costante di sottrazione diversa per sesso (65 cm uomo, 58 donna) e cut-off diverso. Riconosce il rischio cardiovascolare meglio del BMI.
A28: 24 | B28: Cardiometabolic Index | C28: =IF(OR('01 Paziente'!$B$14="",'01 Paziente'!$B$13="",'01 Paziente'!$B$27="",'01 Paziente'!$B$26=""),"n.d.",('01 Paziente'!$B$14/'01 Paziente'!$B$13)*(('01 Paziente'!$B$27/88.57)/('01 Paziente'!$B$26/38.67))) -> n.d. | D28: - | E28: =IF('01 Paziente'!$B$8="M",'02 Riferimenti'!C28,'02 Riferimenti'!E28) -> 0 | F28: =IF('01 Paziente'!$B$8="M",'02 Riferimenti'!D28,'02 Riferimenti'!F28) -> 0.39 | G28: =IF(NOT(ISNUMBER(C28)),"n.d.",IF('02 Riferimenti'!$G$28="Informativo",IF(OR(C28>F28,C28<E28),"fuori fascia","in fascia"),IF(AND(C28>F28,OR('02 Riferimenti'!$G$28="Alto",'02 Riferimenti'!$G$28="Bilaterale")),"Fuori (alto)",IF(AND(C28<E28,OR('02 Riferimenti'!$G$28="Basso",'02 Riferimenti'!$G$28="Bilaterale")),"Fuori (basso)",IF(OR(C28>F28,C28<E28),"Fuori (non critico)",IF(AND('02 Riferimenti'!$G$28<>"Informativo",F28<>E28,OR(AND(OR('02 Riferimenti'!$G$28="Alto",'02 Riferimenti'!$G$28="Bilaterale"),(C28-E28)/(F28-E28)>0.8),AND(OR('02 Riferimenti'!$G$28="Basso",'02 Riferimenti'!$G$28="Bilaterale"),(C28-E28)/(F28-E28)<0.2))),"Borderline","Normale")))))) -> n.d. | H28: ='02 Riferimenti'!$H$28 -> 2 | I28: =IF(OR(G28="n.d.",H28=0),"",IF(AND(C28>F28,OR('02 Riferimenti'!$G$28="Alto",'02 Riferimenti'!$G$28="Bilaterale")),IF((C28-F28)/MAX(F28-E28,0.0001)>0.1,3,2),IF(AND(C28<E28,OR('02 Riferimenti'!$G$28="Basso",'02 Riferimenti'!$G$28="Bilaterale")),IF((E28-C28)/MAX(F28-E28,0.0001)>0.1,3,2),IF(G28="Borderline",1,0)))) | J28: =IF(I28="","",H28*I28) | K28: ='02 Riferimenti'!$I$28 -> Vita | L28: Da calcolare in mmol/L: con i mg/dL il numero non ha rapporto con il cut-off. Soglia piu bassa nella donna.
A29: 25 | B29: Visceral Adiposity Index | C29: =IF(OR('01 Paziente'!$B$14="",'01 Paziente'!$B$55="",'01 Paziente'!$B$27="",'01 Paziente'!$B$26=""),"n.d.",IF('01 Paziente'!$B$8="M",('01 Paziente'!$B$14/(39.68+1.88*'01 Paziente'!$B$55))*(('01 Paziente'!$B$27/88.57)/1.03)*(1.31/('01 Paziente'!$B$26/38.67)),('01 Paziente'!$B$14/(36.58+1.89*'01 Paziente'!$B$55))*(('01 Paziente'!$B$27/88.57)/0.81)*(1.52/('01 Paziente'!$B$26/38.67)))) -> n.d. | D29: - | E29: =IF('01 Paziente'!$B$8="M",'02 Riferimenti'!C29,'02 Riferimenti'!E29) -> 0 | F29: =IF('01 Paziente'!$B$8="M",'02 Riferimenti'!D29,'02 Riferimenti'!F29) -> 1.92 | G29: =IF(NOT(ISNUMBER(C29)),"n.d.",IF('02 Riferimenti'!$G$29="Informativo",IF(OR(C29>F29,C29<E29),"fuori fascia","in fascia"),IF(AND(C29>F29,OR('02 Riferimenti'!$G$29="Alto",'02 Riferimenti'!$G$29="Bilaterale")),"Fuori (alto)",IF(AND(C29<E29,OR('02 Riferimenti'!$G$29="Basso",'02 Riferimenti'!$G$29="Bilaterale")),"Fuori (basso)",IF(OR(C29>F29,C29<E29),"Fuori (non critico)",IF(AND('02 Riferimenti'!$G$29<>"Informativo",F29<>E29,OR(AND(OR('02 Riferimenti'!$G$29="Alto",'02 Riferimenti'!$G$29="Bilaterale"),(C29-E29)/(F29-E29)>0.8),AND(OR('02 Riferimenti'!$G$29="Basso",'02 Riferimenti'!$G$29="Bilaterale"),(C29-E29)/(F29-E29)<0.2))),"Borderline","Normale")))))) -> n.d. | H29: ='02 Riferimenti'!$H$29 -> 3 | I29: =IF(OR(G29="n.d.",H29=0),"",IF(AND(C29>F29,OR('02 Riferimenti'!$G$29="Alto",'02 Riferimenti'!$G$29="Bilaterale")),IF((C29-F29)/MAX(F29-E29,0.0001)>0.1,3,2),IF(AND(C29<E29,OR('02 Riferimenti'!$G$29="Basso",'02 Riferimenti'!$G$29="Bilaterale")),IF((E29-C29)/MAX(F29-E29,0.0001)>0.1,3,2),IF(G29="Borderline",1,0)))) | J29: =IF(I29="","",H29*I29) | K29: ='02 Riferimenti'!$I$29 -> Vita | L29: FORMULA COMPLETAMENTE DIVERSA PER SESSO: tutti e tre i gruppi di coefficienti cambiano. Misura la funzione del tessuto adiposo, non la sua quantita.
A30: 26 | B30: Uricemia | C30: =IF('01 Paziente'!$B$28="","n.d.",'01 Paziente'!$B$28) -> n.d. | D30: mg/dL | E30: =IF('01 Paziente'!$B$8="M",'02 Riferimenti'!C30,'02 Riferimenti'!E30) -> 3.5 | F30: =IF('01 Paziente'!$B$8="M",'02 Riferimenti'!D30,'02 Riferimenti'!F30) -> 7.2 | G30: =IF(NOT(ISNUMBER(C30)),"n.d.",IF('02 Riferimenti'!$G$30="Informativo",IF(OR(C30>F30,C30<E30),"fuori fascia","in fascia"),IF(AND(C30>F30,OR('02 Riferimenti'!$G$30="Alto",'02 Riferimenti'!$G$30="Bilaterale")),"Fuori (alto)",IF(AND(C30<E30,OR('02 Riferimenti'!$G$30="Basso",'02 Riferimenti'!$G$30="Bilaterale")),"Fuori (basso)",IF(OR(C30>F30,C30<E30),"Fuori (non critico)",IF(AND('02 Riferimenti'!$G$30<>"Informativo",F30<>E30,OR(AND(OR('02 Riferimenti'!$G$30="Alto",'02 Riferimenti'!$G$30="Bilaterale"),(C30-E30)/(F30-E30)>0.8),AND(OR('02 Riferimenti'!$G$30="Basso",'02 Riferimenti'!$G$30="Bilaterale"),(C30-E30)/(F30-E30)<0.2))),"Borderline","Normale")))))) -> n.d. | H30: ='02 Riferimenti'!$H$30 -> 2 | I30: =IF(OR(G30="n.d.",H30=0),"",IF(AND(C30>F30,OR('02 Riferimenti'!$G$30="Alto",'02 Riferimenti'!$G$30="Bilaterale")),IF((C30-F30)/MAX(F30-E30,0.0001)>0.1,3,2),IF(AND(C30<E30,OR('02 Riferimenti'!$G$30="Basso",'02 Riferimenti'!$G$30="Bilaterale")),IF((E30-C30)/MAX(F30-E30,0.0001)>0.1,3,2),IF(G30="Borderline",1,0)))) | J30: =IF(I30="","",H30*I30) | K30: ='02 Riferimenti'!$I$30 -> Uricemia | L30: Intervalli molto diversi per sesso.
A31: 27 | B31: Uricemia / HDL | C31: =IF(OR('01 Paziente'!$B$28="",'01 Paziente'!$B$26=""),"n.d.",'01 Paziente'!$B$28/'01 Paziente'!$B$26*100) -> n.d. | D31: - | E31: =IF('01 Paziente'!$B$8="M",'02 Riferimenti'!C31,'02 Riferimenti'!E31) -> 0 | F31: =IF('01 Paziente'!$B$8="M",'02 Riferimenti'!D31,'02 Riferimenti'!F31) -> 12.2 | G31: =IF(NOT(ISNUMBER(C31)),"n.d.",IF('02 Riferimenti'!$G$31="Informativo",IF(OR(C31>F31,C31<E31),"fuori fascia","in fascia"),IF(AND(C31>F31,OR('02 Riferimenti'!$G$31="Alto",'02 Riferimenti'!$G$31="Bilaterale")),"Fuori (alto)",IF(AND(C31<E31,OR('02 Riferimenti'!$G$31="Basso",'02 Riferimenti'!$G$31="Bilaterale")),"Fuori (basso)",IF(OR(C31>F31,C31<E31),"Fuori (non critico)",IF(AND('02 Riferimenti'!$G$31<>"Informativo",F31<>E31,OR(AND(OR('02 Riferimenti'!$G$31="Alto",'02 Riferimenti'!$G$31="Bilaterale"),(C31-E31)/(F31-E31)>0.8),AND(OR('02 Riferimenti'!$G$31="Basso",'02 Riferimenti'!$G$31="Bilaterale"),(C31-E31)/(F31-E31)<0.2))),"Borderline","Normale")))))) -> n.d. | H31: ='02 Riferimenti'!$H$31 -> 2 | I31: =IF(OR(G31="n.d.",H31=0),"",IF(AND(C31>F31,OR('02 Riferimenti'!$G$31="Alto",'02 Riferimenti'!$G$31="Bilaterale")),IF((C31-F31)/MAX(F31-E31,0.0001)>0.1,3,2),IF(AND(C31<E31,OR('02 Riferimenti'!$G$31="Basso",'02 Riferimenti'!$G$31="Bilaterale")),IF((E31-C31)/MAX(F31-E31,0.0001)>0.1,3,2),IF(G31="Borderline",1,0)))) | J31: =IF(I31="","",H31*I31) | K31: ='02 Riferimenti'!$I$31 -> Uricemia | L31: Soglia piu bassa nella donna, coerente con l'uricemia piu bassa.
A32: 28 | B32: Omocisteina | C32: =IF('01 Paziente'!$B$29="","n.d.",'01 Paziente'!$B$29) -> n.d. | D32: uM | E32: =IF('01 Paziente'!$B$8="M",'02 Riferimenti'!C32,'02 Riferimenti'!E32) -> 3 | F32: =IF('01 Paziente'!$B$8="M",'02 Riferimenti'!D32,'02 Riferimenti'!F32) -> 15 | G32: =IF(NOT(ISNUMBER(C32)),"n.d.",IF('02 Riferimenti'!$G$32="Informativo",IF(OR(C32>F32,C32<E32),"fuori fascia","in fascia"),IF(AND(C32>F32,OR('02 Riferimenti'!$G$32="Alto",'02 Riferimenti'!$G$32="Bilaterale")),"Fuori (alto)",IF(AND(C32<E32,OR('02 Riferimenti'!$G$32="Basso",'02 Riferimenti'!$G$32="Bilaterale")),"Fuori (basso)",IF(OR(C32>F32,C32<E32),"Fuori (non critico)",IF(AND('02 Riferimenti'!$G$32<>"Informativo",F32<>E32,OR(AND(OR('02 Riferimenti'!$G$32="Alto",'02 Riferimenti'!$G$32="Bilaterale"),(C32-E32)/(F32-E32)>0.8),AND(OR('02 Riferimenti'!$G$32="Basso",'02 Riferimenti'!$G$32="Bilaterale"),(C32-E32)/(F32-E32)<0.2))),"Borderline","Normale")))))) -> n.d. | H32: ='02 Riferimenti'!$H$32 -> 2 | I32: =IF(OR(G32="n.d.",H32=0),"",IF(AND(C32>F32,OR('02 Riferimenti'!$G$32="Alto",'02 Riferimenti'!$G$32="Bilaterale")),IF((C32-F32)/MAX(F32-E32,0.0001)>0.1,3,2),IF(AND(C32<E32,OR('02 Riferimenti'!$G$32="Basso",'02 Riferimenti'!$G$32="Bilaterale")),IF((E32-C32)/MAX(F32-E32,0.0001)>0.1,3,2),IF(G32="Borderline",1,0)))) | J32: =IF(I32="","",H32*I32) | K32: ='02 Riferimenti'!$I$32 -> Omocisteina | L32: Finestra desiderabile molto piu stretta del riferimento tollerato: 5,0-7,2 uM.
A33: 29 | B33: Saturazione della transferrina | C33: =IF(OR('01 Paziente'!$B$32="",'01 Paziente'!$B$33=""),"n.d.",'01 Paziente'!$B$32/('01 Paziente'!$B$33*1.404)*100) -> n.d. | D33: % | E33: =IF('01 Paziente'!$B$8="M",'02 Riferimenti'!C33,'02 Riferimenti'!E33) -> 20 | F33: =IF('01 Paziente'!$B$8="M",'02 Riferimenti'!D33,'02 Riferimenti'!F33) -> 48 | G33: =IF(NOT(ISNUMBER(C33)),"n.d.",IF('02 Riferimenti'!$G$33="Informativo",IF(OR(C33>F33,C33<E33),"fuori fascia","in fascia"),IF(AND(C33>F33,OR('02 Riferimenti'!$G$33="Alto",'02 Riferimenti'!$G$33="Bilaterale")),"Fuori (alto)",IF(AND(C33<E33,OR('02 Riferimenti'!$G$33="Basso",'02 Riferimenti'!$G$33="Bilaterale")),"Fuori (basso)",IF(OR(C33>F33,C33<E33),"Fuori (non critico)",IF(AND('02 Riferimenti'!$G$33<>"Informativo",F33<>E33,OR(AND(OR('02 Riferimenti'!$G$33="Alto",'02 Riferimenti'!$G$33="Bilaterale"),(C33-E33)/(F33-E33)>0.8),AND(OR('02 Riferimenti'!$G$33="Basso",'02 Riferimenti'!$G$33="Bilaterale"),(C33-E33)/(F33-E33)<0.2))),"Borderline","Normale")))))) -> n.d. | H33: ='02 Riferimenti'!$H$33 -> 3 | I33: =IF(OR(G33="n.d.",H33=0),"",IF(AND(C33>F33,OR('02 Riferimenti'!$G$33="Alto",'02 Riferimenti'!$G$33="Bilaterale")),IF((C33-F33)/MAX(F33-E33,0.0001)>0.1,3,2),IF(AND(C33<E33,OR('02 Riferimenti'!$G$33="Basso",'02 Riferimenti'!$G$33="Bilaterale")),IF((E33-C33)/MAX(F33-E33,0.0001)>0.1,3,2),IF(G33="Borderline",1,0)))) | J33: =IF(I33="","",H33*I33) | K33: ='02 Riferimenti'!$I$33 -> Ferro | L33: Il marcatore piu informativo dello stato marziale reale. TIBC ricavata dalla transferrina con il fattore stechiometrico esatto (mg/dL x 1,404 = ug/dL), non con la regola pratica dell'1,25 che sottostima la capacita legante di circa il 12%.
A34: 30 | B34: Ferritina | C34: =IF('01 Paziente'!$B$34="","n.d.",'01 Paziente'!$B$34) -> n.d. | D34: ug/L | E34: =IF('01 Paziente'!$B$8="M",'02 Riferimenti'!C34,'02 Riferimenti'!E34) -> 30 | F34: =IF('01 Paziente'!$B$8="M",'02 Riferimenti'!D34,'02 Riferimenti'!F34) -> 400 | G34: =IF(NOT(ISNUMBER(C34)),"n.d.",IF('02 Riferimenti'!$G$34="Informativo",IF(OR(C34>F34,C34<E34),"fuori fascia","in fascia"),IF(AND(C34>F34,OR('02 Riferimenti'!$G$34="Alto",'02 Riferimenti'!$G$34="Bilaterale")),"Fuori (alto)",IF(AND(C34<E34,OR('02 Riferimenti'!$G$34="Basso",'02 Riferimenti'!$G$34="Bilaterale")),"Fuori (basso)",IF(OR(C34>F34,C34<E34),"Fuori (non critico)",IF(AND('02 Riferimenti'!$G$34<>"Informativo",F34<>E34,OR(AND(OR('02 Riferimenti'!$G$34="Alto",'02 Riferimenti'!$G$34="Bilaterale"),(C34-E34)/(F34-E34)>0.8),AND(OR('02 Riferimenti'!$G$34="Basso",'02 Riferimenti'!$G$34="Bilaterale"),(C34-E34)/(F34-E34)<0.2))),"Borderline","Normale")))))) -> n.d. | H34: ='02 Riferimenti'!$H$34 -> 2 | I34: =IF(OR(G34="n.d.",H34=0),"",IF(AND(C34>F34,OR('02 Riferimenti'!$G$34="Alto",'02 Riferimenti'!$G$34="Bilaterale")),IF((C34-F34)/MAX(F34-E34,0.0001)>0.1,3,2),IF(AND(C34<E34,OR('02 Riferimenti'!$G$34="Basso",'02 Riferimenti'!$G$34="Bilaterale")),IF((E34-C34)/MAX(F34-E34,0.0001)>0.1,3,2),IF(G34="Borderline",1,0)))) | J34: =IF(I34="","",H34*I34) | K34: ='02 Riferimenti'!$I$34 -> Ferro | L34: INTERVALLI MOLTO DIVERSI PER SESSO. Da non leggere da sola se la PCR e alterata: il foglio 01 lo segnala.
A35: 31 | B35: Emoglobina | C35: =IF('01 Paziente'!$B$39="","n.d.",'01 Paziente'!$B$39) -> n.d. | D35: g/dL | E35: =IF('01 Paziente'!$B$8="M",'02 Riferimenti'!C35,'02 Riferimenti'!E35) -> 13 | F35: =IF('01 Paziente'!$B$8="M",'02 Riferimenti'!D35,'02 Riferimenti'!F35) -> 17.5 | G35: =IF(NOT(ISNUMBER(C35)),"n.d.",IF('02 Riferimenti'!$G$35="Informativo",IF(OR(C35>F35,C35<E35),"fuori fascia","in fascia"),IF(AND(C35>F35,OR('02 Riferimenti'!$G$35="Alto",'02 Riferimenti'!$G$35="Bilaterale")),"Fuori (alto)",IF(AND(C35<E35,OR('02 Riferimenti'!$G$35="Basso",'02 Riferimenti'!$G$35="Bilaterale")),"Fuori (basso)",IF(OR(C35>F35,C35<E35),"Fuori (non critico)",IF(AND('02 Riferimenti'!$G$35<>"Informativo",F35<>E35,OR(AND(OR('02 Riferimenti'!$G$35="Alto",'02 Riferimenti'!$G$35="Bilaterale"),(C35-E35)/(F35-E35)>0.8),AND(OR('02 Riferimenti'!$G$35="Basso",'02 Riferimenti'!$G$35="Bilaterale"),(C35-E35)/(F35-E35)<0.2))),"Borderline","Normale")))))) -> n.d. | H35: ='02 Riferimenti'!$H$35 -> 3 | I35: =IF(OR(G35="n.d.",H35=0),"",IF(AND(C35>F35,OR('02 Riferimenti'!$G$35="Alto",'02 Riferimenti'!$G$35="Bilaterale")),IF((C35-F35)/MAX(F35-E35,0.0001)>0.1,3,2),IF(AND(C35<E35,OR('02 Riferimenti'!$G$35="Basso",'02 Riferimenti'!$G$35="Bilaterale")),IF((E35-C35)/MAX(F35-E35,0.0001)>0.1,3,2),IF(G35="Borderline",1,0)))) | J35: =IF(I35="","",H35*I35) | K35: ='02 Riferimenti'!$I$35 -> Emoglobina | L35: Soglia di anemia 13 g/dL nell'uomo, 12 nella donna.
A36: 32 | B36: Emoglobina / RDW | C36: =IF(OR('01 Paziente'!$B$39="",'01 Paziente'!$B$40=""),"n.d.",'01 Paziente'!$B$39/'01 Paziente'!$B$40) -> n.d. | D36: - | E36: =IF('01 Paziente'!$B$8="M",'02 Riferimenti'!C36,'02 Riferimenti'!E36) -> 1 | F36: =IF('01 Paziente'!$B$8="M",'02 Riferimenti'!D36,'02 Riferimenti'!F36) -> 1.6 | G36: =IF(NOT(ISNUMBER(C36)),"n.d.",IF('02 Riferimenti'!$G$36="Informativo",IF(OR(C36>F36,C36<E36),"fuori fascia","in fascia"),IF(AND(C36>F36,OR('02 Riferimenti'!$G$36="Alto",'02 Riferimenti'!$G$36="Bilaterale")),"Fuori (alto)",IF(AND(C36<E36,OR('02 Riferimenti'!$G$36="Basso",'02 Riferimenti'!$G$36="Bilaterale")),"Fuori (basso)",IF(OR(C36>F36,C36<E36),"Fuori (non critico)",IF(AND('02 Riferimenti'!$G$36<>"Informativo",F36<>E36,OR(AND(OR('02 Riferimenti'!$G$36="Alto",'02 Riferimenti'!$G$36="Bilaterale"),(C36-E36)/(F36-E36)>0.8),AND(OR('02 Riferimenti'!$G$36="Basso",'02 Riferimenti'!$G$36="Bilaterale"),(C36-E36)/(F36-E36)<0.2))),"Borderline","Normale")))))) -> n.d. | H36: ='02 Riferimenti'!$H$36 -> 2 | I36: =IF(OR(G36="n.d.",H36=0),"",IF(AND(C36>F36,OR('02 Riferimenti'!$G$36="Alto",'02 Riferimenti'!$G$36="Bilaterale")),IF((C36-F36)/MAX(F36-E36,0.0001)>0.1,3,2),IF(AND(C36<E36,OR('02 Riferimenti'!$G$36="Basso",'02 Riferimenti'!$G$36="Bilaterale")),IF((E36-C36)/MAX(F36-E36,0.0001)>0.1,3,2),IF(G36="Borderline",1,0)))) | J36: =IF(I36="","",H36*I36) | K36: ='02 Riferimenti'!$I$36 -> Emoglobina | L36: Cala quando il midollo produce eritrociti di taglia irregolare.
A37: 33 | B37: Proteina C reattiva | C37: =IF('01 Paziente'!$B$37="","n.d.",'01 Paziente'!$B$37) -> n.d. | D37: mg/dL | E37: =IF('01 Paziente'!$B$8="M",'02 Riferimenti'!C37,'02 Riferimenti'!E37) -> 0 | F37: =IF('01 Paziente'!$B$8="M",'02 Riferimenti'!D37,'02 Riferimenti'!F37) -> 0.5 | G37: =IF(NOT(ISNUMBER(C37)),"n.d.",IF('02 Riferimenti'!$G$37="Informativo",IF(OR(C37>F37,C37<E37),"fuori fascia","in fascia"),IF(AND(C37>F37,OR('02 Riferimenti'!$G$37="Alto",'02 Riferimenti'!$G$37="Bilaterale")),"Fuori (alto)",IF(AND(C37<E37,OR('02 Riferimenti'!$G$37="Basso",'02 Riferimenti'!$G$37="Bilaterale")),"Fuori (basso)",IF(OR(C37>F37,C37<E37),"Fuori (non critico)",IF(AND('02 Riferimenti'!$G$37<>"Informativo",F37<>E37,OR(AND(OR('02 Riferimenti'!$G$37="Alto",'02 Riferimenti'!$G$37="Bilaterale"),(C37-E37)/(F37-E37)>0.8),AND(OR('02 Riferimenti'!$G$37="Basso",'02 Riferimenti'!$G$37="Bilaterale"),(C37-E37)/(F37-E37)<0.2))),"Borderline","Normale")))))) -> n.d. | H37: ='02 Riferimenti'!$H$37 -> 0 | I37: =IF(OR(G37="n.d.",H37=0),"",IF(AND(C37>F37,OR('02 Riferimenti'!$G$37="Alto",'02 Riferimenti'!$G$37="Bilaterale")),IF((C37-F37)/MAX(F37-E37,0.0001)>0.1,3,2),IF(AND(C37<E37,OR('02 Riferimenti'!$G$37="Basso",'02 Riferimenti'!$G$37="Bilaterale")),IF((E37-C37)/MAX(F37-E37,0.0001)>0.1,3,2),IF(G37="Borderline",1,0)))) | J37: =IF(I37="","",H37*I37) | K37: ='02 Riferimenti'!$I$37 -> Infiammazione classica | L37: Peso 0: esame giusto per la domanda sbagliata. Intercetta l'infiammazione acuta, non quella cronica di basso grado. Serve pero a dire se la ferritina e leggibile.
